Workbook

Sheet Ввод 2026
A1: Итого | B1: =SUBTOTAL(109,B3:B199) -> 5980 | C1: =SUBTOTAL(109,C3:C199) -> 6037 | D1: =SUBTOTAL(109,D3:D199) -> 57
A2: Номенклатура | B2: 46022 | C2: 46053 | D2: Ввод 01.26
A3: Подъемник коленчатый дизельный Dingli BA16CRT2 | B3: =VLOOKUP(A3,'31.12.25'!A:F,2,FALSE) -> 17 | C3: =VLOOKUP(A3,'31.01.26'!A:F,6,FALSE) -> 17 | D3: =C3-B3 -> 0
A4: Подъемник коленчатый дизельный Dingli BA16СRT | B4: =VLOOKUP(A4,'31.12.25'!A:F,2,FALSE) -> 13 | C4: =VLOOKUP(A4,'31.01.26'!A:F,6,FALSE) -> 13 | D4: =C4-B4 -> 0
A5: Подъемник коленчатый дизельный Dingli BA18CRT | B5: =VLOOKUP(A5,'31.12.25'!A:F,2,FALSE) -> 14 | C5: =VLOOKUP(A5,'31.01.26'!A:F,6,FALSE) -> 14 | D5: =C5-B5 -> 0
A6: Подъемник коленчатый дизельный Dingli BA18CRT2 | B6: =VLOOKUP(A6,'31.12.25'!A:F,2,FALSE) -> 200 | C6: =VLOOKUP(A6,'31.01.26'!A:F,6,FALSE) -> 206 | D6: =C6-B6 -> 6
A7: Подъемник коленчатый дизельный Dingli BA22CRT | B7: =VLOOKUP(A7,'31.12.25'!A:F,2,FALSE) -> 15 | C7: =VLOOKUP(A7,'31.01.26'!A:F,6,FALSE) -> 15 | D7: =C7-B7 -> 0
A8: Подъемник коленчатый дизельный Dingli BA22CRT2 | B8: =VLOOKUP(A8,'31.12.25'!A:F,2,FALSE) -> 29 | C8: =VLOOKUP(A8,'31.01.26'!A:F,6,FALSE) -> 29 | D8: =C8-B8 -> 0
A9: Подъемник коленчатый дизельный Dingli BA22CRT2 4WS | B9: =VLOOKUP(A9,'31.12.25'!A:F,2,FALSE) -> 48 | C9: =VLOOKUP(A9,'31.01.26'!A:F,6,FALSE) -> 48 | D9: =C9-B9 -> 0
A10: Подъемник коленчатый дизельный Dingli BA28BRT | B10: =VLOOKUP(A10,'31.12.25'!A:F,2,FALSE) -> 10 | C10: =VLOOKUP(A10,'31.01.26'!A:F,6,FALSE) -> 15 | D10: =C10-B10 -> 5
A11: Подъемник коленчатый дизельный Dingli BA28RT | B11: =VLOOKUP(A11,'31.12.25'!A:F,2,FALSE) -> 87 | C11: =VLOOKUP(A11,'31.01.26'!A:F,6,FALSE) -> 87 | D11: =C11-B11 -> 0
A12: Подъемник коленчатый дизельный Dingli BA36RT | B12: =VLOOKUP(A12,'31.12.25'!A:F,2,FALSE) -> 32 | C12: =VLOOKUP(A12,'31.01.26'!A:F,6,FALSE) -> 32 | D12: =C12-B12 -> 0
A13: Подъемник коленчатый дизельный Dingli BA41RT | B13: =VLOOKUP(A13,'31.12.25'!A:F,2,FALSE) -> 22 | C13: =VLOOKUP(A13,'31.01.26'!A:F,6,FALSE) -> 22 | D13: =C13-B13 -> 0
A14: Подъемник коленчатый дизельный Dingli BA44RT | B14: =VLOOKUP(A14,'31.12.25'!A:F,2,FALSE) -> 94 | C14: =VLOOKUP(A14,'31.01.26'!A:F,6,FALSE) -> 94 | D14: =C14-B14 -> 0
... A142: Подъемник ножничный электрический Sinoboom 0608N | B142: =VLOOKUP(A142,'31.12.25'!A:F,2,FALSE) -> 3 | C142: =VLOOKUP(A142,'31.01.26'!A:F,6,FALSE) -> 3 | D142: =C142-B142 -> 0
A143: Подъемник ножничный электрический Sinoboom 0608N-Li | B143: 0 | C143: 0 | D143: =C143-B143 -> 0
A144: Подъемник ножничный электрический Sinoboom 0808N | B144: =VLOOKUP(A144,'31.12.25'!A:F,2,FALSE) -> 24 | C144: =VLOOKUP(A144,'31.01.26'!A:F,6,FALSE) -> 24 | D144: =C144-B144 -> 0
A145: Подъемник ножничный электрический Sinoboom 0808N-Li | B145: =VLOOKUP(A145,'31.12.25'!A:F,2,FALSE) -> 8 | C145: =VLOOKUP(A145,'31.01.26'!A:F,6,FALSE) -> 8 | D145: =C145-B145 -> 0
A146: Подъемник ножничный электрический Sinoboom 1012N | B146: =VLOOKUP(A146,'31.12.25'!A:F,2,FALSE) -> 18 | C146: =VLOOKUP(A146,'31.01.26'!A:F,6,FALSE) -> 18 | D146: =C146-B146 -> 0
A147: Подъемник ножничный электрический Sinoboom 1012N-Li | B147: =VLOOKUP(A147,'31.12.25'!A:F,2,FALSE) -> 4 | C147: =VLOOKUP(A147,'31.01.26'!A:F,6,FALSE) -> 4 | D147: =C147-B147 -> 0
A148: Подъемник ножничный электрический Sinoboom 1212N | B148: =VLOOKUP(A148,'31.12.25'!A:F,2,FALSE) -> 18 | C148: =VLOOKUP(A148,'31.01.26'!A:F,6,FALSE) -> 18 | D148: =C148-B148 -> 0
A149: Подъемник ножничный электрический Sinoboom 1212N-Li | B149: =VLOOKUP(A149,'31.12.25'!A:F,2,FALSE) -> 17 | C149: =VLOOKUP(A149,'31.01.26'!A:F,6,FALSE) -> 17 | D149: =C149-B149 -> 0
A150: Подъемник ножничный электрический Sinoboom 1414Plus | B150: =VLOOKUP(A150,'31.12.25'!A:F,2,FALSE) -> 17 | C150: =VLOOKUP(A150,'31.01.26'!A:F,6,FALSE) -> 17 | D150: =C150-B150 -> 0
A151: Подъемник ножничный электрический Sinoboom 1414Plus-Li | B151: =VLOOKUP(A151,'31.12.25'!A:F,2,FALSE) -> 5 | C151: =VLOOKUP(A151,'31.01.26'!A:F,6,FALSE) -> 5 | D151: =C151-B151 -> 0
A152: Подъемник ножничный электрический Sinoboom GTJZ0808 | B152: =VLOOKUP(A152,'31.12.25'!A:F,2,FALSE) -> 20 | C152: =VLOOKUP(A152,'31.01.26'!A:F,6,FALSE) -> 20 | D152: =C152-B152 -> 0
A153: Подъемник ножничный электрический Sinoboom GTJZ1212 | B153: =VLOOKUP(A153,'31.12.25'!A:F,2,FALSE) -> 17 | C153: =VLOOKUP(A153,'31.01.26'!A:F,6,FALSE) -> 17 | D153: =C153-B153 -> 0
A154: Подъемник ножничный электрический Sinoboom GTJZ1412 | B154: =VLOOKUP(A154,'31.12.25'!A:F,2,FALSE) -> 16 | C154: =VLOOKUP(A154,'31.01.26'!A:F,6,FALSE) -> 16 | D154: =C154-B154 -> 0
A155: Подъемник ножничный электрический Zoomlion ZS0407DC | B155: =VLOOKUP(A155,'31.12.25'!A:F,2,FALSE) -> 9 | C155: =VLOOKUP(A155,'31.01.26'!A:F,6,FALSE) -> 9 | D155: =C155-B155 -> 0
... A199: Подъёмник телескопический дизельный Zoomlion ZT58J | B199: =VLOOKUP(A199,'31.12.25'!A:F,2,FALSE) -> 1 | C199: =VLOOKUP(A199,'31.01.26'!A:F,6,FALSE) -> 1 | D199: =C199-B199 -> 0

Sheet 31.01.26
A1: Номенклатура | B1: Итого
B2: В аренде, шт | C2: На складе, шт | D2: Рем зона | E2: Брак | F2: Всего, шт | G2: Утилизация без брака, % | H2: Утилизация, %
A3: Подъемник коленчатый дизельный Dingli BA16CRT2 | B3: 13 | C3: 4 | F3: 17 | G3: 76.47 | H3: 76.47
A4: Подъемник коленчатый дизельный Dingli BA16СRT | B4: 10 | C4: 3 | F4: 13 | G4: 76.92 | H4: 76.92
A5: Подъемник коленчатый дизельный Dingli BA18CRT | B5: 11 | C5: 2 | F5: 14 | G5: 84.62 | H5: 84.62
A6: Подъемник коленчатый дизельный Dingli BA18CRT2 | B6: 167 | C6: 35 | D6: 4 | F6: 206 | G6: 81.07 | H6: 81.07
A7: Подъемник коленчатый дизельный Dingli BA22CRT | B7: 9 | C7: 6 | F7: 15 | G7: 60 | H7: 60
A8: Подъемник коленчатый дизельный Dingli BA22CRT2 | B8: 25 | C8: 4 | F8: 29 | G8: 86.21 | H8: 86.21
A9: Подъемник коленчатый дизельный Dingli BA22CRT2 4WS | B9: 37 | C9: 11 | F9: 48 | G9: 77.08 | H9: 77.08
A10: Подъемник коленчатый дизельный Dingli BA28BRT | B10: 13 | C10: 2 | F10: 15 | G10: 86.67 | H10: 86.67
A11: Подъемник коленчатый дизельный Dingli BA28RT | B11: 73 | C11: 12 | D11: 1 | E11: 1 | F11: 87 | G11: 84.88 | H11: 83.91
A12: Подъемник коленчатый дизельный Dingli BA36RT | B12: 19 | C12: 13 | F12: 32 | G12: 59.38 | H12: 59.38
A13: Подъемник коленчатый дизельный Dingli BA41RT | B13: 20 | C13: 2 | F13: 22 | G13: 90.91 | H13: 90.91
A14: Подъемник коленчатый дизельный Dingli BA44RT | B14: 77 | C14: 14 | D14: 2 | E14: 1 | F14: 94 | G14: 82.8 | H14: 81.91
A15: Подъемник коленчатый дизельный Genie Z-45/25 | B15: 0 | C15: 1 | F15: 1 | H15: 0
A16: Подъемник коленчатый дизельный Genie Z-51/30J | B16: 5 | C16: 1 | F16: 6 | G16: 83.33 | H16: 83.33
A17: Подъемник коленчатый дизельный Genie Z-62/40 | B17: 2 | F17: 2 | G17: 100 | H17: 100
A18: Подъемник коленчатый дизельный HAULOTTE HA16RTJ | B18: 1 | C18: 1 | F18: 2 | G18: 50 | H18: 50
A19: Подъемник коленчатый дизельный HAULOTTE HA20RTJ | B19: 4 | C19: 3 | F19: 7 | G19: 57.14 | H19: 57.14
A20: Подъемник коленчатый дизельный HAULOTTE HA26RTJ PRO | B20: 3 | C20: 3 | F20: 6 | G20: 50 | H20: 50
A21: Подъемник коленчатый дизельный JLG 520AJ | B21: 4 | C21: 3 | D21: 1 | E21: 1 | F21: 9 | G21: 50 | H21: 44.44
A22: Подъемник коленчатый дизельный JLG 600AJ | B22: 1 | D22: 2 | F22: 3 | G22: 33.33 | H22: 33.33
A23: Подъемник коленчатый дизельный LGMG AR14J | B23: 5 | C23: 6 | D23: 2 | F23: 13 | G23: 38.46 | H23: 38.46
A24: Подъемник коленчатый дизельный LGMG AR16J | B24: 8 | C24: 12 | D24: 1 | E24: 1 | F24: 22 | G24: 38.1 | H24: 36.36
A25: Подъемник коленчатый дизельный MANITOU 180 ATJ | B25: 1 | F25: 1 | G25: 100 | H25: 100
A26: Подъемник коленчатый дизельный MANITOU 200 ATJ-X | B26: 2 | C26: 1 | F26: 3 | G26: 66.67 | H26: 66.67
A27: Подъемник коленчатый дизельный Sinoboom AB15J | B27: 70 | C27: 26 | D27: 1 | E27: 1 | F27: 98 | G27: 72.16 | H27: 71.43
A28: Подъемник коленчатый дизельный Sinoboom AB18J | B28: 112 | C28: 33 | D28: 4 | E28: 1 | F28: 150 | G28: 75.17 | H28: 74.67
A29: Подъемник коленчатый дизельный Sinoboom AB22J Plus | B29: 44 | C29: 5 | F29: 49 | G29: 89.8 | H29: 89.8
A30: Подъёмник коленчатый дизельный Sinoboom AB25J | B30: 1 | C30: 4 | F30: 5 | G30: 20 | H30: 20
A31: Подъемник коленчатый дизельный Sinoboom AB26J Plus | B31: 81 | C31: 31 | D31: 1 | E31: 1 | F31: 114 | G31: 71.68 | H31: 71.05
A32: Подъемник коленчатый дизельный Sinoboom AB46RJ | B32: 35 | F32: 35 | G32: 100 | H32: 100
A33: Подъемник коленчатый дизельный Zoomlion ZA14J | B33: 164 | C33: 62 | D33: 2 | F33: 228 | G33: 71.93 | H33: 71.93
A34: Подъемник коленчатый дизельный Zoomlion ZA16J | B34: 15 | C34: 5 | F34: 20 | G34: 75 | H34: 75
A35: Подъемник коленчатый дизельный Zoomlion ZA20J | B35: 216 | C35: 32 | D35: 2 | E35: 1 | F35: 251 | G35: 86.4 | H35: 86.06
A36: Подъемник коленчатый дизельный Zoomlion ZA24J | B36: 117 | C36: 57 | D36: 1 | E36: 3 | F36: 178 | G36: 66.86 | H36: 65.73
A37: Подъемник коленчатый дизельный Zoomlion ZA32J | B37: 153 | C37: 30 | D37: 1 | E37: 3 | F37: 187 | G37: 83.15 | H37: 81.82
A38: Подъемник коленчатый дизельный Zoomlion ZA42J | B38: 4 | C38: 4 | F38: 8 | G38: 50 | H38: 50
A39: Подъемник коленчатый электрический Aurora ART3.8JE(F) | B39: 63 | C39: 11 | E39: 1 | F39: 75 | G39: 85.14 | H39: 84
A40: Подъемник коленчатый электрический Dingli BA18NE | B40: 14 | C40: 9 | F40: 23 | G40: 60.87 | H40: 60.87
...

Sheet Ввод 2025
A1: Итого | B1: =SUBTOTAL(109,B3:B199) -> 2944 | C1: =SUBTOTAL(109,C3:C199) -> 3002 | D1: =SUBTOTAL(109,D3:D199) -> 58 | E1: =SUBTOTAL(109,E3:E199) -> 3186 | F1: =SUBTOTAL(109,F3:F199) -> 184 | G1: =SUBTOTAL(109,G3:G199) -> 3275 | H1: =SUBTOTAL(109,H3:H199) -> 89 | I1: =SUBTOTAL(109,I3:I199) -> 3483 | ... AA1: =SUBTOTAL(109,AA3:AA199) -> 3036
A2: Номенклатура | B2: 45657 | C2: 45688 | D2: Ввод 01.25 | E2: 45716 | F2: Ввод 02.25 | G2: 45747 | H2: Ввод 03.25 | I2: 45777 | J2: Ввод 04.25 | K2: 45808 | L2: Ввод 05.25 | M2: 45838 | N2: Ввод 06.25 | O2: 45869 | P2: Ввод 07.25 | Q2: 45900 | R2: Ввод 08.25 | S2: 45930 | T2: Ввод 09.25 | U2: 45961 | V2: Ввод 10.25 | W2: 45991 | X2: Ввод 11.25 | Y2: 46022 | Z2: Ввод 12.25 | AA2: Ввод 2025
A3: Подъемник мачтовый электрический Aurora AMWP3.6-6100 (Rees) | B3: =VLOOKUP(A3,'31.12.24'!A:F,6,FALSE) -> 5 | C3: =VLOOKUP(A3,'31.01.25'!A:F,6,FALSE) -> 5 | D3: =C3-B3 -> 0 | E3: =VLOOKUP(A3,'28.02.25'!A:F,6,FALSE) -> 5 | F3: =E3-C3 -> 0 | G3: =VLOOKUP(A3,'31.03.25'!A:F,6,FALSE) -> 5 | H3: =G3-E3 -> 0 | I3: =VLOOKUP(A3,'30.04.25'!A:F,6,FALSE) -> 5 | J3: =I3-G3 -> 0 | K3: =VLOOKUP(A3,'31.05.25'!A:F,6,FALSE) -> 5 | L3: =K3-I3 -> 0 | M3: =VLOOKUP(A3,'30.06.25'!A:F,6,FALSE) -> 5 | N3: =M3-K3 -> 0 | O3: =VLOOKUP(A3,'31.07.25'!A:F,6,FALSE) -> 5 | P3: =O3-M3 -> 0 | Q3: =VLOOKUP(A3,'31.08.25'!A:F,6,FALSE) -> 5 | R3: =Q3-O3 -> 0 | S3: =VLOOKUP(A3,'30.09.25'!A:F,6,FALSE) -> 5 | T3: =S3-Q3 -> 0 | U3: =VLOOKUP(A3,'31.10.25'!A:F,6,FALSE) -> 5 | V3: =U3-S3 -> 0 | W3: =VLOOKUP(A3,'30.11.25'!A:F,6,FALSE) -> 5 | X3: =W3-U3 -> 0 | Y3: =VLOOKUP(A3,'31.12.25'!A:B,2,FALSE) -> 5 | Z3: =Y3-W3 -> 0 | AA3: =Y3-B3 -> 0
A4: Подъемник мачтовый электрический Aurora AMWP4.8-6100 (Rees) | B4: =VLOOKUP(A4,'31.12.24'!A:F,6,FALSE) -> 6 | C4: =VLOOKUP(A4,'31.01.25'!A:F,6,FALSE) -> 6 | D4: =C4-B4 -> 0 | E4: =VLOOKUP(A4,'28.02.25'!A:F,6,FALSE) -> 6 | F4: =E4-C4 -> 0 | G4: =VLOOKUP(A4,'31.03.25'!A:F,6,FALSE) -> 6 | H4: =G4-E4 -> 0 | I4: =VLOOKUP(A4,'30.04.25'!A:F,6,FALSE) -> 6 | J4: =I4-G4 -> 0 | K4: =VLOOKUP(A4,'31.05.25'!A:F,6,FALSE) -> 6 | L4: =K4-I4 -> 0 | M4: =VLOOKUP(A4,'30.06.25'!A:F,6,FALSE) -> 5 | N4: =M4-K4 -> -1 | O4: =VLOOKUP(A4,'31.07.25'!A:F,6,FALSE) -> 5 | P4: =O4-M4 -> 0 | Q4: =VLOOKUP(A4,'31.08.25'!A:F,6,FALSE) -> 5 | R4: =Q4-O4 -> 0 | S4: =VLOOKUP(A4,'30.09.25'!A:F,6,FALSE) -> 5 | T4: =S4-Q4 -> 0 | U4: =VLOOKUP(A4,'31.10.25'!A:F,6,FALSE) -> 5 | V4: =U4-S4 -> 0 | W4: =VLOOKUP(A4,'30.11.25'!A:F,6,FALSE) -> 5 | X4: =W4-U4 -> 0 | Y4: =VLOOKUP(A4,'31.12.25'!A:B,2,FALSE) -> 5 | Z4: =Y4-W4 -> 0 | AA4: =Y4-B4 -> -1
A5: Подъемник мачтовый электрический Aurora AMWP7.5-1100 (Rees) | B5: =VLOOKUP(A5,'31.12.24'!A:F,6,FALSE) -> 1 | C5: =VLOOKUP(A5,'31.01.25'!A:F,6,FALSE) -> 1 | D5: =C5-B5 -> 0 | E5: =VLOOKUP(A5,'28.02.25'!A:F,6,FALSE) -> 1 | F5: =E5-C5 -> 0 | G5: =VLOOKUP(A5,'31.03.25'!A:F,6,FALSE) -> 1 | H5: =G5-E5 -> 0 | I5: =VLOOKUP(A5,'30.04.25'!A:F,6,FALSE) -> 1 | J5: =I5-G5 -> 0 | K5: =VLOOKUP(A5,'31.05.25'!A:F,6,FALSE) -> 1 | L5: =K5-I5 -> 0 | M5: =VLOOKUP(A5,'30.06.25'!A:F,6,FALSE) -> 1 | N5: =M5-K5 -> 0 | O5: =VLOOKUP(A5,'31.07.25'!A:F,6,FALSE) -> 1 | P5: =O5-M5 -> 0 | Q5: =VLOOKUP(A5,'31.08.25'!A:F,6,FALSE) -> 1 | R5: =Q5-O5 -> 0 | S5: =VLOOKUP(A5,'30.09.25'!A:F,6,FALSE) -> 1 | T5: =S5-Q5 -> 0 | U5: =VLOOKUP(A5,'31.10.25'!A:F,6,FALSE) -> 1 | V5: =U5-S5 -> 0 | W5: =VLOOKUP(A5,'30.11.25'!A:F,6,FALSE) -> 1 | X5: =W5-U5 -> 0 | Y5: =VLOOKUP(A5,'31.12.25'!A:B,2,FALSE) -> 1 | Z5: =Y5-W5 -> 0 | AA5: =Y5-B5 -> 0
A6: Подъемник мачтовый электрический Aurora AMWP7.5-2100 (Rees) | B6: =VLOOKUP(A6,'31.12.24'!A:F,6,FALSE) -> 2 | C6: =VLOOKUP(A6,'31.01.25'!A:F,6,FALSE) -> 2 | D6: =C6-B6 -> 0 | E6: =VLOOKUP(A6,'28.02.25'!A:F,6,FALSE) -> 2 | F6: =E6-C6 -> 0 | G6: =VLOOKUP(A6,'31.03.25'!A:F,6,FALSE) -> 2 | H6: =G6-E6 -> 0 | I6: =VLOOKUP(A6,'30.04.25'!A:F,6,FALSE) -> 2 | J6: =I6-G6 -> 0 | K6: =VLOOKUP(A6,'31.05.25'!A:F,6,FALSE) -> 2 | L6: =K6-I6 -> 0 | M6: =VLOOKUP(A6,'30.06.25'!A:F,6,FALSE) -> 2 | N6: =M6-K6 -> 0 | O6: =VLOOKUP(A6,'31.07.25'!A:F,6,FALSE) -> 2 | P6: =O6-M6 -> 0 | Q6: =VLOOKUP(A6,'31.08.25'!A:F,6,FALSE) -> 2 | R6: =Q6-O6 -> 0 | S6: =VLOOKUP(A6,'30.09.25'!A:F,6,FALSE) -> 2 | T6: =S6-Q6 -> 0 | U6: =VLOOKUP(A6,'31.10.25'!A:F,6,FALSE) -> 2 | V6: =U6-S6 -> 0 | W6: =VLOOKUP(A6,'30.11.25'!A:F,6,FALSE) -> 2 | X6: =W6-U6 -> 0 | Y6: =VLOOKUP(A6,'31.12.25'!A:B,2,FALSE) -> 2 | Z6: =Y6-W6 -> 0 | AA6: =Y6-B6 -> 0
A7: Подъемник мачтовый электрический Aurora AMWP9-2100 (Rees) | B7: =VLOOKUP(A7,'31.12.24'!A:F,6,FALSE) -> 1 | C7: =VLOOKUP(A7,'31.01.25'!A:F,6,FALSE) -> 1 | D7: =C7-B7 -> 0 | E7: =VLOOKUP(A7,'28.02.25'!A:F,6,FALSE) -> 1 | F7: =E7-C7 -> 0 | G7: =VLOOKUP(A7,'31.03.25'!A:F,6,FALSE) -> 1 | H7: =G7-E7 -> 0 | I7: =VLOOKUP(A7,'30.04.25'!A:F,6,FALSE) -> 1 | J7: =I7-G7 -> 0 | K7: =VLOOKUP(A7,'31.05.25'!A:F,6,FALSE) -> 1 | L7: =K7-I7 -> 0 | M7: =VLOOKUP(A7,'30.06.25'!A:F,6,FALSE) -> 1 | N7: =M7-K7 -> 0 | O7: =VLOOKUP(A7,'31.07.25'!A:F,6,FALSE) -> 1 | P7: =O7-M7 -> 0 | Q7: =VLOOKUP(A7,'31.08.25'!A:F,6,FALSE) -> 1 | R7: =Q7-O7 -> 0 | S7: =VLOOKUP(A7,'30.09.25'!A:F,6,FALSE) -> 1 | T7: =S7-Q7 -> 0 | U7: =VLOOKUP(A7,'31.10.25'!A:F,6,FALSE) -> 1 | V7: =U7-S7 -> 0 | W7: =VLOOKUP(A7,'30.11.25'!A:F,6,FALSE) -> 1 | X7: =W7-U7 -> 0 | Y7: =VLOOKUP(A7,'31.12.25'!A:B,2,FALSE) -> 1 | Z7: =Y7-W7 -> 0 | AA7: =Y7-B7 -> 0
A8: Подъемник коленчатый дизельный Dingli BA16CRT2 | B8: =VLOOKUP(A8,'31.12.24'!A:F,6,FALSE) -> 17 | C8: =VLOOKUP(A8,'31.01.25'!A:F,6,FALSE) -> 17 | D8: =C8-B8 -> 0 | E8: =VLOOKUP(A8,'28.02.25'!A:F,6,FALSE) -> 17 | F8: =E8-C8 -> 0 | G8: =VLOOKUP(A8,'31.03.25'!A:F,6,FALSE) -> 17 | H8: =G8-E8 -> 0 | I8: =VLOOKUP(A8,'30.04.25'!A:F,6,FALSE) -> 17 | J8: =I8-G8 -> 0 | K8: =VLOOKUP(A8,'31.05.25'!A:F,6,FALSE) -> 17 | L8: =K8-I8 -> 0 | M8: =VLOOKUP(A8,'30.06.25'!A:F,6,FALSE) -> 17 | N8: =M8-K8 -> 0 | O8: =VLOOKUP(A8,'31.07.25'!A:F,6,FALSE) -> 17 | P8: =O8-M8 -> 0 | Q8: =VLOOKUP(A8,'31.08.25'!A:F,6,FALSE) -> 17 | R8: =Q8-O8 -> 0 | S8: =VLOOKUP(A8,'30.09.25'!A:F,6,FALSE) -> 17 | T8: =S8-Q8 -> 0 | U8: =VLOOKUP(A8,'31.10.25'!A:F,6,FALSE) -> 17 | V8: =U8-S8 -> 0 | W8: =VLOOKUP(A8,'30.11.25'!A:F,6,FALSE) -> 17 | X8: =W8-U8 -> 0 | Y8: =VLOOKUP(A8,'31.12.25'!A:B,2,FALSE) -> 17 | Z8: =Y8-W8 -> 0 | AA8: =Y8-B8 -> 0
A9: Подъемник коленчатый дизельный Dingli BA16СRT | B9: =VLOOKUP(A9,'31.12.24'!A:F,6,FALSE) -> 13 | C9: =VLOOKUP(A9,'31.01.25'!A:F,6,FALSE) -> 13 | D9: =C9-B9 -> 0 | E9: =VLOOKUP(A9,'28.02.25'!A:F,6,FALSE) -> 13 | F9: =E9-C9 -> 0 | G9: =VLOOKUP(A9,'31.03.25'!A:F,6,FALSE) -> 13 | H9: =G9-E9 -> 0 | I9: =VLOOKUP(A9,'30.04.25'!A:F,6,FALSE) -> 13 | J9: =I9-G9 -> 0 | K9: =VLOOKUP(A9,'31.05.25'!A:F,6,FALSE) -> 13 | L9: =K9-I9 -> 0 | M9: =VLOOKUP(A9,'30.06.25'!A:F,6,FALSE) -> 13 | N9: =M9-K9 -> 0 | O9: =VLOOKUP(A9,'31.07.25'!A:F,6,FALSE) -> 13 | P9: =O9-M9 -> 0 | Q9: =VLOOKUP(A9,'31.08.25'!A:F,6,FALSE) -> 13 | R9: =Q9-O9 -> 0 | S9: =VLOOKUP(A9,'30.09.25'!A:F,6,FALSE) -> 13 | T9: =S9-Q9 -> 0 | U9: =VLOOKUP(A9,'31.10.25'!A:F,6,FALSE) -> 13 | V9: =U9-S9 -> 0 | W9: =VLOOKUP(A9,'30.11.25'!A:F,6,FALSE) -> 13 | X9: =W9-U9 -> 0 | Y9: =VLOOKUP(A9,'31.12.25'!A:B,2,FALSE) -> 13 | Z9: =Y9-W9 -> 0 | AA9: =Y9-B9 -> 0
A10: Подъемник коленчатый дизельный Dingli BA18CRT | B10: =VLOOKUP(A10,'31.12.24'!A:F,6,FALSE) -> 13 | C10: =VLOOKUP(A10,'31.01.25'!A:F,6,FALSE) -> 13 | D10: =C10-B10 -> 0 | E10: =VLOOKUP(A10,'28.02.25'!A:F,6,FALSE) -> 13 | F10: =E10-C10 -> 0 | G10: =VLOOKUP(A10,'31.03.25'!A:F,6,FALSE) -> 13 | H10: =G10-E10 -> 0 | I10: =VLOOKUP(A10,'30.04.25'!A:F,6,FALSE) -> 13 | J10: =I10-G10 -> 0 | K10: =VLOOKUP(A10,'31.05.25'!A:F,6,FALSE) -> 13 | L10: =K10-I10 -> 0 | M10: =VLOOKUP(A10,'30.06.25'!A:F,6,FALSE) -> 13 | N10: =M10-K10 -> 0 | O10: =VLOOKUP(A10,'31.07.25'!A:F,6,FALSE) -> 13 | P10: =O10-M10 -> 0 | Q10: =VLOOKUP(A10,'31.08.25'!A:F,6,FALSE) -> 13 | R10: =Q10-O10 -> 0 | S10: =VLOOKUP(A10,'30.09.25'!A:F,6,FALSE) -> 14 | T10: =S10-Q10 -> 1 | U10: =VLOOKUP(A10,'31.10.25'!A:F,6,FALSE) -> 14 | V10: =U10-S10 -> 0 | W10: =VLOOKUP(A10,'30.11.25'!A:F,6,FALSE) -> 14 | X10: =W10-U10 -> 0 | Y10: =VLOOKUP(A10,'31.12.25'!A:B,2,FALSE) -> 14 | Z10: =Y10-W10 -> 0 | AA10: =Y10-B10 -> 1
A11: Подъемник коленчатый дизельный Dingli BA18CRT2 | B11: =VLOOKUP(A11,'31.12.24'!A:F,6,FALSE) -> 68 | C11: =VLOOKUP(A11,'31.01.25'!A:F,6,FALSE) -> 70 | D11: =C11-B11 -> 2 | E11: =VLOOKUP(A11,'28.02.25'!A:F,6,FALSE) -> 84 | F11: =E11-C11 -> 14 | G11: =VLOOKUP(A11,'31.03.25'!A:F,6,FALSE) -> 84 | H11: =G11-E11 -> 0 | I11: =VLOOKUP(A11,'30.04.25'!A:F,6,FALSE) -> 87 | J11: =I11-G11 -> 3 | K11: =VLOOKUP(A11,'31.05.25'!A:F,6,FALSE) -> 87 | L11: =K11-I11 -> 0 | M11: =VLOOKUP(A11,'30.06.25'!A:F,6,FALSE) -> 87 | N11: =M11-K11 -> 0 | O11: =VLOOKUP(A11,'31.07.25'!A:F,6,FALSE) -> 107 | P11: =O11-M11 -> 20 | Q11: =VLOOKUP(A11,'31.08.25'!A:F,6,FALSE) -> 131 | R11: =Q11-O11 -> 24 | S11: =VLOOKUP(A11,'30.09.25'!A:F,6,FALSE) -> 149 | T11: =S11-Q11 -> 18 | U11: =VLOOKUP(A11,'31.10.25'!A:F,6,FALSE) -> 178 | V11: =U11-S11 -> 29 | W11: =VLOOKUP(A11,'30.11.25'!A:F,6,FALSE) -> 184 | X11: =W11-U11 -> 6 | Y11: =VLOOKUP(A11,'31.12.25'!A:B,2,FALSE) -> 200 | Z11: =Y11-W11 -> 16 | AA11: =Y11-B11 -> 132
A12: Подъемник коленчатый дизельный Dingli BA22CRT | B12: =VLOOKUP(A12,'31.12.24'!A:F,6,FALSE) -> 15 | C12: =VLOOKUP(A12,'31.01.25'!A:F,6,FALSE) -> 15 | D12: =C12-B12 -> 0 | E12: =VLOOKUP(A12,'28.02.25'!A:F,6,FALSE) -> 15 | F12: =E12-C12 -> 0 | G12: =VLOOKUP(A12,'31.03.25'!A:F,6,FALSE) -> 15 | H12: =G12-E12 -> 0 | I12: =VLOOKUP(A12,'30.04.25'!A:F,6,FALSE) -> 15 | J12: =I12-G12 -> 0 | K12: =VLOOKUP(A12,'31.05.25'!A:F,6,FALSE) -> 15 | L12: =K12-I12 -> 0 | M12: =VLOOKUP(A12,'30.06.25'!A:F,6,FALSE) -> 15 | N12: =M12-K12 -> 0 | O12: =VLOOKUP(A12,'31.07.25'!A:F,6,FALSE) -> 15 | P12: =O12-M12 -> 0 | Q12: =VLOOKUP(A12,'31.08.25'!A:F,6,FALSE) -> 15 | R12: =Q12-O12 -> 0 | S12: =VLOOKUP(A12,'30.09.25'!A:F,6,FALSE) -> 15 | T12: =S12-Q12 -> 0 | U12: =VLOOKUP(A12,'31.10.25'!A:F,6,FALSE) -> 15 | V12: =U12-S12 -> 0 | W12: =VLOOKUP(A12,'30.11.25'!A:F,6,FALSE) -> 15 | X12: =W12-U12 -> 0 | Y12: =VLOOKUP(A12,'31.12.25'!A:B,2,FALSE) -> 15 | Z12: =Y12-W12 -> 0 | AA12: =Y12-B12 -> 0
A13: Подъемник коленчатый дизельный Dingli BA22CRT2 | B13: =VLOOKUP(A13,'31.12.24'!A:F,6,FALSE) -> 24 | C13: =VLOOKUP(A13,'31.01.25'!A:F,6,FALSE) -> 24 | D13: =C13-B13 -> 0 | E13: =VLOOKUP(A13,'28.02.25'!A:F,6,FALSE) -> 24 | F13: =E13-C13 -> 0 | G13: =VLOOKUP(A13,'31.03.25'!A:F,6,FALSE) -> 24 | H13: =G13-E13 -> 0 | I13: =VLOOKUP(A13,'30.04.25'!A:F,6,FALSE) -> 24 | J13: =I13-G13 -> 0 | K13: =VLOOKUP(A13,'31.05.25'!A:F,6,FALSE) -> 24 | L13: =K13-I13 -> 0 | M13: =VLOOKUP(A13,'30.06.25'!A:F,6,FALSE) -> 24 | N13: =M13-K13 -> 0 | O13: =VLOOKUP(A13,'31.07.25'!A:F,6,FALSE) -> 24 | P13: =O13-M13 -> 0 | Q13: =VLOOKUP(A13,'31.08.25'!A:F,6,FALSE) -> 27 | R13: =Q13-O13 -> 3 | S13: =VLOOKUP(A13,'30.09.25'!A:F,6,FALSE) -> 27 | T13: =S13-Q13 -> 0 | U13: =VLOOKUP(A13,'31.10.25'!A:F,6,FALSE) -> 29 | V13: =U13-S13 -> 2 | W13: =VLOOKUP(A13,'30.11.25'!A:F,6,FALSE) -> 29 | X13: =W13-U13 -> 0 | Y13: =VLOOKUP(A13,'31.12.25'!A:B,2,FALSE) -> 29 | Z13: =Y13-W13 -> 0 | AA13: =Y13-B13 -> 5
A14: Подъемник коленчатый дизельный Dingli BA22CRT2 4WS | C14: =VLOOKUP(A14,'31.01.25'!A:F,6,FALSE) -> 2 | D14: =C14-B14 -> 2 | E14: =VLOOKUP(A14,'28.02.25'!A:F,6,FALSE) -> 10 | F14: =E14-C14 -> 8 | G14: =VLOOKUP(A14,'31.03.25'!A:F,6,FALSE) -> 10 | H14: =G14-E14 -> 0 | I14: =VLOOKUP(A14,'30.04.25'!A:F,6,FALSE) -> 16 | J14: =I14-G14 -> 6 | K14: =VLOOKUP(A14,'31.05.25'!A:F,6,FALSE) -> 16 | L14: =K14-I14 -> 0 | M14: =VLOOKUP(A14,'30.06.25'!A:F,6,FALSE) -> 16 | N14: =M14-K14 -> 0 | O14: =VLOOKUP(A14,'31.07.25'!A:F,6,FALSE) -> 17 | P14: =O14-M14 -> 1 | Q14: =VLOOKUP(A14,'31.08.25'!A:F,6,FALSE) -> 27 | R14: =Q14-O14 -> 10 | S14: =VLOOKUP(A14,'30.09.25'!A:F,6,FALSE) -> 30 | T14: =S14-Q14 -> 3 | U14: =VLOOKUP(A14,'31.10.25'!A:F,6,FALSE) -> 38 | V14: =U14-S14 -> 8 | W14: =VLOOKUP(A14,'30.11.25'!A:F,6,FALSE) -> 46 | X14: =W14-U14 -> 8 | Y14: =VLOOKUP(A14,'31.12.25'!A:B,2,FALSE) -> 48 | Z14: =Y14-W14 -> 2 | AA14: =Y14-B14 -> 48
A15: Подъемник коленчатый дизельный Dingli BA28BRT | B15: =VLOOKUP(A15,'31.12.24'!A:F,6,FALSE) -> 6 | C15: =VLOOKUP(A15,'31.01.25'!A:F,6,FALSE) -> 6 | D15: =C15-B15 -> 0 | E15: =VLOOKUP(A15,'28.02.25'!A:F,6,FALSE) -> 6 | F15: =E15-C15 -> 0 | G15: =VLOOKUP(A15,'31.03.25'!A:F,6,FALSE) -> 6 | H15: =G15-E15 -> 0 | I15: =VLOOKUP(A15,'30.04.25'!A:F,6,FALSE) -> 6 | J15: =I15-G15 -> 0 | K15: =VLOOKUP(A15,'31.05.25'!A:F,6,FALSE) -> 6 | L15: =K15-I15 -> 0 | M15: =VLOOKUP(A15,'30.06.25'!A:F,6,FALSE) -> 6 | N15: =M15-K15 -> 0 | O15: =VLOOKUP(A15,'31.07.25'!A:F,6,FALSE) -> 6 | P15: =O15-M15 -> 0 | Q15: =VLOOKUP(A15,'31.08.25'!A:F,6,FALSE) -> 6 | R15: =Q15-O15 -> 0 | S15: =VLOOKUP(A15,'30.09.25'!A:F,6,FALSE) -> 8 | T15: =S15-Q15 -> 2 | U15: =VLOOKUP(A15,'31.10.25'!A:F,6,FALSE) -> 9 | V15: =U15-S15 -> 1 | W15: =VLOOKUP(A15,'30.11.25'!A:F,6,FALSE) -> 10 | X15: =W15-U15 -> 1 | Y15: =VLOOKUP(A15,'31.12.25'!A:B,2,FALSE) -> 10 | Z15: =Y15-W15 -> 0 | AA15: =Y15-B15 -> 4
A16: Подъемник коленчатый дизельный Dingli BA28RT | B16: =VLOOKUP(A16,'31.12.24'!A:F,6,FALSE) -> 62 | C16: =VLOOKUP(A16,'31.01.25'!A:F,6,FALSE) -> 62 | D16: =C16-B16 -> 0 | E16: =VLOOKUP(A16,'28.02.25'!A:F,6,FALSE) -> 62 | F16: =E16-C16 -> 0 | G16: =VLOOKUP(A16,'31.03.25'!A:F,6,FALSE) -> 62 | H16: =G16-E16 -> 0 | I16: =VLOOKUP(A16,'30.04.25'!A:F,6,FALSE) -> 66 | J16: =I16-G16 -> 4 | K16: =VLOOKUP(A16,'31.05.25'!A:F,6,FALSE) -> 66 | L16: =K16-I16 -> 0 | M16: =VLOOKUP(A16,'30.06.25'!A:F,6,FALSE) -> 69 | N16: =M16-K16 -> 3 | O16: =VLOOKUP(A16,'31.07.25'!A:F,6,FALSE) -> 71 | P16: =O16-M16 -> 2 | Q16: =VLOOKUP(A16,'31.08.25'!A:F,6,FALSE) -> 81 | R16: =Q16-O16 -> 10 | S16: =VLOOKUP(A16,'30.09.25'!A:F,6,FALSE) -> 84 | T16: =S16-Q16 -> 3 | U16: =VLOOKUP(A16,'31.10.25'!A:F,6,FALSE) -> 87 | V16: =U16-S16 -> 3 | W16: =VLOOKUP(A16,'30.11.25'!A:F,6,FALSE) -> 87 | X16: =W16-U16 -> 0 | Y16: =VLOOKUP(A16,'31.12.25'!A:B,2,FALSE) -> 87 | Z16: =Y16-W16 -> 0 | AA16: =Y16-B16 -> 25
A17: Подъемник коленчатый дизельный Dingli BA36RT | D17: =C17-B17 -> 0 | F17: =E17-C17 -> 0 | H17: =G17-E17 -> 0 | I17: =VLOOKUP(A17,'30.04.25'!A:F,6,FALSE) -> 1 | J17: =I17-G17 -> 1 | K17: =VLOOKUP(A17,'31.05.25'!A:F,6,FALSE) -> 6 | L17: =K17-I17 -> 5 | M17: =VLOOKUP(A17,'30.06.25'!A:F,6,FALSE) -> 12 | N17: =M17-K17 -> 6 | O17: =VLOOKUP(A17,'31.07.25'!A:F,6,FALSE) -> 22 | P17: =O17-M17 -> 10 | Q17: =VLOOKUP(A17,'31.08.25'!A:F,6,FALSE) -> 24 | R17: =Q17-O17 -> 2 | S17: =VLOOKUP(A17,'30.09.25'!A:F,6,FALSE) -> 28 | T17: =S17-Q17 -> 4 | U17: =VLOOKUP(A17,'31.10.25'!A:F,6,FALSE) -> 28 | V17: =U17-S17 -> 0 | W17: =VLOOKUP(A17,'30.11.25'!A:F,6,FALSE) -> 28 | X17: =W17-U17 -> 0 | Y17: =VLOOKUP(A17,'31.12.25'!A:B,2,FALSE) -> 32 | Z17: =Y17-W17 -> 4 | AA17: =Y17-B17 -> 32
A18: Подъемник коленчатый дизельный Dingli BA41RT | B18: =VLOOKUP(A18,'31.12.24'!A:F,6,FALSE) -> 9 | C18: =VLOOKUP(A18,'31.01.25'!A:F,6,FALSE) -> 9 | D18: =C18-B18 -> 0 | E18: =VLOOKUP(A18,'28.02.25'!A:F,6,FALSE) -> 9 | F18: =E18-C18 -> 0 | G18: =VLOOKUP(A18,'31.03.25'!A:F,6,FALSE) -> 9 | H18: =G18-E18 -> 0 | I18: =VLOOKUP(A18,'30.04.25'!A:F,6,FALSE) -> 9 | J18: =I18-G18 -> 0 | K18: =VLOOKUP(A18,'31.05.25'!A:F,6,FALSE) -> 9 | L18: =K18-I18 -> 0 | M18: =VLOOKUP(A18,'30.06.25'!A:F,6,FALSE) -> 9 | N18: =M18-K18 -> 0 | O18: =VLOOKUP(A18,'31.07.25'!A:F,6,FALSE) -> 9 | P18: =O18-M18 -> 0 | Q18: =VLOOKUP(A18,'31.08.25'!A:F,6,FALSE) -> 18 | R18: =Q18-O18 -> 9 | S18: =VLOOKUP(A18,'30.09.25'!A:F,6,FALSE) -> 18 | T18: =S18-Q18 -> 0 | U18: =VLOOKUP(A18,'31.10.25'!A:F,6,FALSE) -> 22 | V18: =U18-S18 -> 4 | W18: =VLOOKUP(A18,'30.11.25'!A:F,6,FALSE) -> 22 | X18: =W18-U18 -> 0 | Y18: =VLOOKUP(A18,'31.12.25'!A:B,2,FALSE) -> 22 | Z18: =Y18-W18 -> 0 | AA18: =Y18-B18 -> 13
A19: Подъемник коленчатый дизельный Dingli BA44RT | B19: =VLOOKUP(A19,'31.12.24'!A:F,6,FALSE) -> 2 | C19: =VLOOKUP(A19,'31.01.25'!A:F,6,FALSE) -> 2 | D19: =C19-B19 -> 0 | E19: =VLOOKUP(A19,'28.02.25'!A:F,6,FALSE) -> 6 | F19: =E19-C19 -> 4 | G19: =VLOOKUP(A19,'31.03.25'!A:F,6,FALSE) -> 7 | H19: =G19-E19 -> 1 | I19: =VLOOKUP(A19,'30.04.25'!A:F,6,FALSE) -> 16 | J19: =I19-G19 -> 9 | K19: =VLOOKUP(A19,'31.05.25'!A:F,6,FALSE) -> 35 | L19: =K19-I19 -> 19 | M19: =VLOOKUP(A19,'30.06.25'!A:F,6,FALSE) -> 53 | N19: =M19-K19 -> 18 | O19: =VLOOKUP(A19,'31.07.25'!A:F,6,FALSE) -> 64 | P19: =O19-M19 -> 11 | Q19: =VLOOKUP(A19,'31.08.25'!A:F,6,FALSE) -> 79 | R19: =Q19-O19 -> 15 | S19: =VLOOKUP(A19,'30.09.25'!A:F,6,FALSE) -> 82 | T19: =S19-Q19 -> 3 | U19: =VLOOKUP(A19,'31.10.25'!A:F,6,FALSE) -> 85 | V19: =U19-S19 -> 3 | W19: =VLOOKUP(A19,'30.11.25'!A:F,6,FALSE) -> 86 | X19: =W19-U19 -> 1 | Y19: =VLOOKUP(A19,'31.12.25'!A:B,2,FALSE) -> 94 | Z19: =Y19-W19 -> 8 | AA19: =Y19-B19 -> 92
A20: Подъемник коленчатый дизельный Genie Z-45/25 | B20: =VLOOKUP(A20,'31.12.24'!A:F,6,FALSE) -> 1 | C20: =VLOOKUP(A20,'31.01.25'!A:F,6,FALSE) -> 1 | D20: =C20-B20 -> 0 | E20: =VLOOKUP(A20,'28.02.25'!A:F,6,FALSE) -> 1 | F20: =E20-C20 -> 0 | G20: =VLOOKUP(A20,'31.03.25'!A:F,6,FALSE) -> 1 | H20: =G20-E20 -> 0 | I20: =VLOOKUP(A20,'30.04.25'!A:F,6,FALSE) -> 1 | J20: =I20-G20 -> 0 | K20: =VLOOKUP(A20,'31.05.25'!A:F,6,FALSE) -> 1 | L20: =K20-I20 -> 0 | M20: =VLOOKUP(A20,'30.06.25'!A:F,6,FALSE) -> 1 | N20: =M20-K20 -> 0 | O20: =VLOOKUP(A20,'31.07.25'!A:F,6,FALSE) -> 1 | P20: =O20-M20 -> 0 | Q20: =VLOOKUP(A20,'31.08.25'!A:F,6,FALSE) -> 1 | R20: =Q20-O20 -> 0 | S20: =VLOOKUP(A20,'30.09.25'!A:F,6,FALSE) -> 1 | T20: =S20-Q20 -> 0 | U20: =VLOOKUP(A20,'31.10.25'!A:F,6,FALSE) -> 1 | V20: =U20-S20 -> 0 | W20: =VLOOKUP(A20,'30.11.25'!A:F,6,FALSE) -> 1 | X20: =W20-U20 -> 0 | Y20: =VLOOKUP(A20,'31.12.25'!A:B,2,FALSE) -> 1 | Z20: =Y20-W20 -> 0 | AA20: =Y20-B20 -> 0
A21: Подъемник коленчатый дизельный Genie Z-51/30J | B21: =VLOOKUP(A21,'31.12.24'!A:F,6,FALSE) -> 6 | C21: =VLOOKUP(A21,'31.01.25'!A:F,6,FALSE) -> 6 | D21: =C21-B21 -> 0 | E21: =VLOOKUP(A21,'28.02.25'!A:F,6,FALSE) -> 6 | F21: =E21-C21 -> 0 | G21: =VLOOKUP(A21,'31.03.25'!A:F,6,FALSE) -> 6 | H21: =G21-E21 -> 0 | I21: =VLOOKUP(A21,'30.04.25'!A:F,6,FALSE) -> 6 | J21: =I21-G21 -> 0 | K21: =VLOOKUP(A21,'31.05.25'!A:F,6,FALSE) -> 6 | L21: =K21-I21 -> 0 | M21: =VLOOKUP(A21,'30.06.25'!A:F,6,FALSE) -> 6 | N21: =M21-K21 -> 0 | O21: =VLOOKUP(A21,'31.07.25'!A:F,6,FALSE) -> 6 | P21: =O21-M21 -> 0 | Q21: =VLOOKUP(A21,'31.08.25'!A:F,6,FALSE) -> 6 | R21: =Q21-O21 -> 0 | S21: =VLOOKUP(A21,'30.09.25'!A:F,6,FALSE) -> 6 | T21: =S21-Q21 -> 0 | U21: =VLOOKUP(A21,'31.10.25'!A:F,6,FALSE) -> 6 | V21: =U21-S21 -> 0 | W21: =VLOOKUP(A21,'30.11.25'!A:F,6,FALSE) -> 6 | X21: =W21-U21 -> 0 | Y21: =VLOOKUP(A21,'31.12.25'!A:B,2,FALSE) -> 6 | Z21: =Y21-W21 -> 0 | AA21: =Y21-B21 -> 0
A22: Подъемник коленчатый дизельный Genie Z-62/40 | B22: =VLOOKUP(A22,'31.12.24'!A:F,6,FALSE) -> 2 | C22: =VLOOKUP(A22,'31.01.25'!A:F,6,FALSE) -> 2 | D22: =C22-B22 -> 0 | E22: =VLOOKUP(A22,'28.02.25'!A:F,6,FALSE) -> 2 | F22: =E22-C22 -> 0 | G22: =VLOOKUP(A22,'31.03.25'!A:F,6,FALSE) -> 2 | H22: =G22-E22 -> 0 | I22: =VLOOKUP(A22,'30.04.25'!A:F,6,FALSE) -> 2 | J22: =I22-G22 -> 0 | K22: =VLOOKUP(A22,'31.05.25'!A:F,6,FALSE) -> 2 | L22: =K22-I22 -> 0 | M22: =VLOOKUP(A22,'30.06.25'!A:F,6,FALSE) -> 2 | N22: =M22-K22 -> 0 | O22: =VLOOKUP(A22,'31.07.25'!A:F,6,FALSE) -> 2 | P22: =O22-M22 -> 0 | Q22: =VLOOKUP(A22,'31.08.25'!A:F,6,FALSE) -> 2 | R22: =Q22-O22 -> 0 | S22: =VLOOKUP(A22,'30.09.25'!A:F,6,FALSE) -> 2 | T22: =S22-Q22 -> 0 | U22: =VLOOKUP(A22,'31.10.25'!A:F,6,FALSE) -> 2 | V22: =U22-S22 -> 0 | W22: =VLOOKUP(A22,'30.11.25'!A:F,6,FALSE) -> 2 | X22: =W22-U22 -> 0 | Y22: =VLOOKUP(A22,'31.12.25'!A:B,2,FALSE) -> 2 | Z22: =Y22-W22 -> 0 | AA22: =Y22-B22 -> 0
A23: Подъемник коленчатый дизельный HAULOTTE HA16RTJ | B23: =VLOOKUP(A23,'31.12.24'!A:F,6,FALSE) -> 2 | C23: =VLOOKUP(A23,'31.01.25'!A:F,6,FALSE) -> 2 | D23: =C23-B23 -> 0 | E23: =VLOOKUP(A23,'28.02.25'!A:F,6,FALSE) -> 2 | F23: =E23-C23 -> 0 | G23: =VLOOKUP(A23,'31.03.25'!A:F,6,FALSE) -> 2 | H23: =G23-E23 -> 0 | I23: =VLOOKUP(A23,'30.04.25'!A:F,6,FALSE) -> 2 | J23: =I23-G23 -> 0 | K23: =VLOOKUP(A23,'31.05.25'!A:F,6,FALSE) -> 2 | L23: =K23-I23 -> 0 | M23: =VLOOKUP(A23,'30.06.25'!A:F,6,FALSE) -> 2 | N23: =M23-K23 -> 0 | O23: =VLOOKUP(A23,'31.07.25'!A:F,6,FALSE) -> 2 | P23: =O23-M23 -> 0 | Q23: =VLOOKUP(A23,'31.08.25'!A:F,6,FALSE) -> 2 | R23: =Q23-O23 -> 0 | S23: =VLOOKUP(A23,'30.09.25'!A:F,6,FALSE) -> 2 | T23: =S23-Q23 -> 0 | U23: =VLOOKUP(A23,'31.10.25'!A:F,6,FALSE) -> 2 | V23: =U23-S23 -> 0 | W23: =VLOOKUP(A23,'30.11.25'!A:F,6,FALSE) -> 2 | X23: =W23-U23 -> 0 | Y23: =VLOOKUP(A23,'31.12.25'!A:B,2,FALSE) -> 2 | Z23: =Y23-W23 -> 0 | AA23: =Y23-B23 -> 0
A24: Подъемник коленчатый дизельный HAULOTTE HA20RTJ | B24: =VLOOKUP(A24,'31.12.24'!A:F,6,FALSE) -> 7 | C24: =VLOOKUP(A24,'31.01.25'!A:F,6,FALSE) -> 7 | D24: =C24-B24 -> 0 | E24: =VLOOKUP(A24,'28.02.25'!A:F,6,FALSE) -> 7 | F24: =E24-C24 -> 0 | G24: =VLOOKUP(A24,'31.03.25'!A:F,6,FALSE) -> 7 | H24: =G24-E24 -> 0 | I24: =VLOOKUP(A24,'30.04.25'!A:F,6,FALSE) -> 7 | J24: =I24-G24 -> 0 | K24: =VLOOKUP(A24,'31.05.25'!A:F,6,FALSE) -> 7 | L24: =K24-I24 -> 0 | M24: =VLOOKUP(A24,'30.06.25'!A:F,6,FALSE) -> 7 | N24: =M24-K24 -> 0 | O24: =VLOOKUP(A24,'31.07.25'!A:F,6,FALSE) -> 7 | P24: =O24-M24 -> 0 | Q24: =VLOOKUP(A24,'31.08.25'!A:F,6,FALSE) -> 7 | R24: =Q24-O24 -> 0 | S24: =VLOOKUP(A24,'30.09.25'!A:F,6,FALSE) -> 7 | T24: =S24-Q24 -> 0 | U24: =VLOOKUP(A24,'31.10.25'!A:F,6,FALSE) -> 7 | V24: =U24-S24 -> 0 | W24: =VLOOKUP(A24,'30.11.25'!A:F,6,FALSE) -> 7 | X24: =W24-U24 -> 0 | Y24: =VLOOKUP(A24,'31.12.25'!A:B,2,FALSE) -> 7 | Z24: =Y24-W24 -> 0 | AA24: =Y24-B24 -> 0
A25: Подъемник коленчатый дизельный HAULOTTE HA26RTJ PRO | B25: =VLOOKUP(A25,'31.12.24'!A:F,6,FALSE) -> 6 | C25: =VLOOKUP(A25,'31.01.25'!A:F,6,FALSE) -> 6 | D25: =C25-B25 -> 0 | E25: =VLOOKUP(A25,'28.02.25'!A:F,6,FALSE) -> 6 | F25: =E25-C25 -> 0 | G25: =VLOOKUP(A25,'31.03.25'!A:F,6,FALSE) -> 6 | H25: =G25-E25 -> 0 | I25: =VLOOKUP(A25,'30.04.25'!A:F,6,FALSE) -> 6 | J25: =I25-G25 -> 0 | K25: =VLOOKUP(A25,'31.05.25'!A:F,6,FALSE) -> 6 | L25: =K25-I25 -> 0 | M25: =VLOOKUP(A25,'30.06.25'!A:F,6,FALSE) -> 6 | N25: =M25-K25 -> 0 | O25: =VLOOKUP(A25,'31.07.25'!A:F,6,FALSE) -> 6 | P25: =O25-M25 -> 0 | Q25: =VLOOKUP(A25,'31.08.25'!A:F,6,FALSE) -> 6 | R25: =Q25-O25 -> 0 | S25: =VLOOKUP(A25,'30.09.25'!A:F,6,FALSE) -> 6 | T25: =S25-Q25 -> 0 | U25: =VLOOKUP(A25,'31.10.25'!A:F,6,FALSE) -> 6 | V25: =U25-S25 -> 0 | W25: =VLOOKUP(A25,'30.11.25'!A:F,6,FALSE) -> 6 | X25: =W25-U25 -> 0 | Y25: =VLOOKUP(A25,'31.12.25'!A:B,2,FALSE) -> 6 | Z25: =Y25-W25 -> 0 | AA25: =Y25-B25 -> 0
A26: Подъемник коленчатый дизельный JLG 520AJ | B26: =VLOOKUP(A26,'31.12.24'!A:F,6,FALSE) -> 9 | C26: =VLOOKUP(A26,'31.01.25'!A:F,6,FALSE) -> 9 | D26: =C26-B26 -> 0 | E26: =VLOOKUP(A26,'28.02.25'!A:F,6,FALSE) -> 9 | F26: =E26-C26 -> 0 | G26: =VLOOKUP(A26,'31.03.25'!A:F,6,FALSE) -> 9 | H26: =G26-E26 -> 0 | I26: =VLOOKUP(A26,'30.04.25'!A:F,6,FALSE) -> 9 | J26: =I26-G26 -> 0 | K26: =VLOOKUP(A26,'31.05.25'!A:F,6,FALSE) -> 9 | L26: =K26-I26 -> 0 | M26: =VLOOKUP(A26,'30.06.25'!A:F,6,FALSE) -> 9 | N26: =M26-K26 -> 0 | O26: =VLOOKUP(A26,'31.07.25'!A:F,6,FALSE) -> 9 | P26: =O26-M26 -> 0 | Q26: =VLOOKUP(A26,'31.08.25'!A:F,6,FALSE) -> 9 | R26: =Q26-O26 -> 0 | S26: =VLOOKUP(A26,'30.09.25'!A:F,6,FALSE) -> 9 | T26: =S26-Q26 -> 0 | U26: =VLOOKUP(A26,'31.10.25'!A:F,6,FALSE) -> 9 | V26: =U26-S26 -> 0 | W26: =VLOOKUP(A26,'30.11.25'!A:F,6,FALSE) -> 9 | X26: =W26-U26 -> 0 | Y26: =VLOOKUP(A26,'31.12.25'!A:B,2,FALSE) -> 9 | Z26: =Y26-W26 -> 0 | AA26: =Y26-B26 -> 0
A27: Подъемник коленчатый дизельный JLG 600AJ | B27: =VLOOKUP(A27,'31.12.24'!A:F,6,FALSE) -> 3 | C27: =VLOOKUP(A27,'31.01.25'!A:F,6,FALSE) -> 3 | D27: =C27-B27 -> 0 | E27: =VLOOKUP(A27,'28.02.25'!A:F,6,FALSE) -> 3 | F27: =E27-C27 -> 0 | G27: =VLOOKUP(A27,'31.03.25'!A:F,6,FALSE) -> 3 | H27: =G27-E27 -> 0 | I27: =VLOOKUP(A27,'30.04.25'!A:F,6,FALSE) -> 3 | J27: =I27-G27 -> 0 | K27: =VLOOKUP(A27,'31.05.25'!A:F,6,FALSE) -> 3 | L27: =K27-I27 -> 0 | M27: =VLOOKUP(A27,'30.06.25'!A:F,6,FALSE) -> 3 | N27: =M27-K27 -> 0 | O27: =VLOOKUP(A27,'31.07.25'!A:F,6,FALSE) -> 3 | P27: =O27-M27 -> 0 | Q27: =VLOOKUP(A27,'31.08.25'!A:F,6,FALSE) -> 3 | R27: =Q27-O27 -> 0 | S27: =VLOOKUP(A27,'30.09.25'!A:F,6,FALSE) -> 3 | T27: =S27-Q27 -> 0 | U27: =VLOOKUP(A27,'31.10.25'!A:F,6,FALSE) -> 3 | V27: =U27-S27 -> 0 | W27: =VLOOKUP(A27,'30.11.25'!A:F,6,FALSE) -> 3 | X27: =W27-U27 -> 0 | Y27: =VLOOKUP(A27,'31.12.25'!A:B,2,FALSE) -> 3 | Z27: =Y27-W27 -> 0 | AA27: =Y27-B27 -> 0
A28: Подъемник коленчатый дизельный LGMG AR14J | B28: =VLOOKUP(A28,'31.12.24'!A:F,6,FALSE) -> 13 | C28: =VLOOKUP(A28,'31.01.25'!A:F,6,FALSE) -> 13 | D28: =C28-B28 -> 0 | E28: =VLOOKUP(A28,'28.02.25'!A:F,6,FALSE) -> 13 | F28: =E28-C28 -> 0 | G28: =VLOOKUP(A28,'31.03.25'!A:F,6,FALSE) -> 13 | H28: =G28-E28 -> 0 | I28: =VLOOKUP(A28,'30.04.25'!A:F,6,FALSE) -> 13 | J28: =I28-G28 -> 0 | K28: =VLOOKUP(A28,'31.05.25'!A:F,6,FALSE) -> 13 | L28: =K28-I28 -> 0 | M28: =VLOOKUP(A28,'30.06.25'!A:F,6,FALSE) -> 13 | N28: =M28-K28 -> 0 | O28: =VLOOKUP(A28,'31.07.25'!A:F,6,FALSE) -> 13 | P28: =O28-M28 -> 0 | Q28: =VLOOKUP(A28,'31.08.25'!A:F,6,FALSE) -> 13 | R28: =Q28-O28 -> 0 | S28: =VLOOKUP(A28,'30.09.25'!A:F,6,FALSE) -> 13 | T28: =S28-Q28 -> 0 | U28: =VLOOKUP(A28,'31.10.25'!A:F,6,FALSE) -> 13 | V28: =U28-S28 -> 0 | W28: =VLOOKUP(A28,'30.11.25'!A:F,6,FALSE) -> 13 | X28: =W28-U28 -> 0 | Y28: =VLOOKUP(A28,'31.12.25'!A:B,2,FALSE) -> 13 | Z28: =Y28-W28 -> 0 | AA28: =Y28-B28 -> 0
A29: Подъемник коленчатый дизельный LGMG AR16J | B29: =VLOOKUP(A29,'31.12.24'!A:F,6,FALSE) -> 22 | C29: =VLOOKUP(A29,'31.01.25'!A:F,6,FALSE) -> 22 | D29: =C29-B29 -> 0 | E29: =VLOOKUP(A29,'28.02.25'!A:F,6,FALSE) -> 22 | F29: =E29-C29 -> 0 | G29: =VLOOKUP(A29,'31.03.25'!A:F,6,FALSE) -> 22 | H29: =G29-E29 -> 0 | I29: =VLOOKUP(A29,'30.04.25'!A:F,6,FALSE) -> 22 | J29: =I29-G29 -> 0 | K29: =VLOOKUP(A29,'31.05.25'!A:F,6,FALSE) -> 22 | L29: =K29-I29 -> 0 | M29: =VLOOKUP(A29,'30.06.25'!A:F,6,FALSE) -> 22 | N29: =M29-K29 -> 0 | O29: =VLOOKUP(A29,'31.07.25'!A:F,6,FALSE) -> 22 | P29: =O29-M29 -> 0 | Q29: =VLOOKUP(A29,'31.08.25'!A:F,6,FALSE) -> 22 | R29: =Q29-O29 -> 0 | S29: =VLOOKUP(A29,'30.09.25'!A:F,6,FALSE) -> 22 | T29: =S29-Q29 -> 0 | U29: =VLOOKUP(A29,'31.10.25'!A:F,6,FALSE) -> 22 | V29: =U29-S29 -> 0 | W29: =VLOOKUP(A29,'30.11.25'!A:F,6,FALSE) -> 22 | X29: =W29-U29 -> 0 | Y29: =VLOOKUP(A29,'31.12.25'!A:B,2,FALSE) -> 22 | Z29: =Y29-W29 -> 0 | AA29: =Y29-B29 -> 0
... A33: Подъемник коленчатый дизельный Sinoboom AB18J | B33: =VLOOKUP(A33,'31.12.24'!A:F,6,FALSE) -> 52 | C33: =VLOOKUP(A33,'31.01.25'!A:F,6,FALSE) -> 85 | D33: =C33-B33 -> 33 | E33: =VLOOKUP(A33,'28.02.25'!A:F,6,FALSE) -> 89 | F33: =E33-C33 -> 4 | G33: =VLOOKUP(A33,'31.03.25'!A:F,6,FALSE) -> 99 | H33: =G33-E33 -> 10 | I33: =VLOOKUP(A33,'30.04.25'!A:F,6,FALSE) -> 109 | J33: =I33-G33 -> 10 | K33: =VLOOKUP(A33,'31.05.25'!A:F,6,FALSE) -> 109 | L33: =K33-I33 -> 0 | M33: =VLOOKUP(A33,'30.06.25'!A:F,6,FALSE) -> 114 | N33: =M33-K33 -> 5 | O33: =VLOOKUP(A33,'31.07.25'!A:F,6,FALSE) -> 118 | P33: =O33-M33 -> 4 | Q33: =VLOOKUP(A33,'31.08.25'!A:F,6,FALSE) -> 141 | R33: =Q33-O33 -> 23 | S33: =VLOOKUP(A33,'30.09.25'!A:F,6,FALSE) -> 150 | T33: =S33-Q33 -> 9 | U33: =VLOOKUP(A33,'31.10.25'!A:F,6,FALSE) -> 150 | V33: =U33-S33 -> 0 | W33: =VLOOKUP(A33,'30.11.25'!A:F,6,FALSE) -> 150 | X33: =W33-U33 -> 0 | Y33: =VLOOKUP(A33,'31.12.25'!A:B,2,FALSE) -> 150 | Z33: =Y33-W33 -> 0 | AA33: =Y33-B33 -> 98
A34: Подъемник коленчатый дизельный Sinoboom AB22J Plus | D34: =C34-B34 -> 0 | F34: =E34-C34 -> 0 | H34: =G34-E34 -> 0 | J34: =I34-G34 -> 0 | L34: =K34-I34 -> 0 | N34: =M34-K34 -> 0 | P34: =O34-M34 -> 0 | Q34: =VLOOKUP(A34,'31.08.25'!A:F,6,FALSE) -> 19 | R34: =Q34-O34 -> 19 | S34: =VLOOKUP(A34,'30.09.25'!A:F,6,FALSE) -> 20 | T34: =S34-Q34 -> 1 | U34: =VLOOKUP(A34,'31.10.25'!A:F,6,FALSE) -> 43 | V34: =U34-S34 -> 23 | W34: =VLOOKUP(A34,'30.11.25'!A:F,6,FALSE) -> 49 | X34: =W34-U34 -> 6 | Y34: =VLOOKUP(A34,'31.12.25'!A:B,2,FALSE) -> 49 | Z34: =Y34-W34 -> 0 | AA34: =Y34-B34 -> 49
A35: Подъёмник коленчатый дизельный Sinoboom AB25J | D35: =C35-B35 -> 0 | F35: =E35-C35 -> 0 | H35: =G35-E35 -> 0 | J35: =I35-G35 -> 0 | K35: =VLOOKUP(A35,'31.05.25'!A:F,6,FALSE) -> 5 | L35: =K35-I35 -> 5 | M35: =VLOOKUP(A35,'30.06.25'!A:F,6,FALSE) -> 5 | N35: =M35-K35 -> 0 | O35: =VLOOKUP(A35,'31.07.25'!A:F,6,FALSE) -> 5 | P35: =O35-M35 -> 0 | Q35: =VLOOKUP(A35,'31.08.25'!A:F,6,FALSE) -> 5 | R35: =Q35-O35 -> 0 | S35: =VLOOKUP(A35,'30.09.25'!A:F,6,FALSE) -> 5 | T35: =S35-Q35 -> 0 | U35: =VLOOKUP(A35,'31.10.25'!A:F,6,FALSE) -> 5 | V35: =U35-S35 -> 0 | W35: =VLOOKUP(A35,'30.11.25'!A:F,6,FALSE) -> 5 | X35: =W35-U35 -> 0 | Y35: =VLOOKUP(A35,'31.12.25'!A:B,2,FALSE) -> 5 | Z35: =Y35-W35 -> 0 | AA35: =Y35-B35 -> 5
A36: Подъемник коленчатый дизельный Sinoboom AB26J Plus | B36: =VLOOKUP(A36,'31.12.24'!A:F,6,FALSE) -> 16 | C36: =VLOOKUP(A36,'31.01.25'!A:F,6,FALSE) -> 16 | D36: =C36-B36 -> 0 | E36: =VLOOKUP(A36,'28.02.25'!A:F,6,FALSE) -> 40 | F36: =E36-C36 -> 24 | G36: =VLOOKUP(A36,'31.03.25'!A:F,6,FALSE) -> 41 | H36: =G36-E36 -> 1 | I36: =VLOOKUP(A36,'30.04.25'!A:F,6,FALSE) -> 41 | J36: =I36-G36 -> 0 | K36: =VLOOKUP(A36,'31.05.25'!A:F,6,FALSE) -> 51 | L36: =K36-I36 -> 10 | M36: =VLOOKUP(A36,'30.06.25'!A:F,6,FALSE) -> 51 | N36: =M36-K36 -> 0 | O36: =VLOOKUP(A36,'31.07.25'!A:F,6,FALSE) -> 60 | P36: =O36-M36 -> 9 | Q36: =VLOOKUP(A36,'31.08.25'!A:F,6,FALSE) -> 84 | R36: =Q36-O36 -> 24 | S36: =VLOOKUP(A36,'30.09.25'!A:F,6,FALSE) -> 100 | T36: =S36-Q36 -> 16 | U36: =VLOOKUP(A36,'31.10.25'!A:F,6,FALSE) -> 104 | V36: =U36-S36 -> 4 | W36: =VLOOKUP(A36,'30.11.25'!A:F,6,FALSE) -> 114 | X36: =W36-U36 -> 10 | Y36: =VLOOKUP(A36,'31.12.25'!A:B,2,FALSE) -> 114 | Z36: =Y36-W36 -> 0 | AA36: =Y36-B36 -> 98
A37: Подъемник коленчатый дизельный Sinoboom AB46RJ | D37: =C37-B37 -> 0 | F37: =E37-C37 -> 0 | G37: =VLOOKUP(A37,'31.03.25'!A:F,6,FALSE) -> 1 | H37: =G37-E37 -> 1 | I37: =VLOOKUP(A37,'30.04.25'!A:F,6,FALSE) -> 1 | J37: =I37-G37 -> 0 | K37: =VLOOKUP(A37,'31.05.25'!A:F,6,FALSE) -> 1 | L37: =K37-I37 -> 0 | M37: =VLOOKUP(A37,'30.06.25'!A:F,6,FALSE) -> 1 | N37: =M37-K37 -> 0 | O37: =VLOOKUP(A37,'31.07.25'!A:F,6,FALSE) -> 4 | P37: =O37-M37 -> 3 | Q37: =VLOOKUP(A37,'31.08.25'!A:F,6,FALSE) -> 14 | R37: =Q37-O37 -> 10 | S37: =VLOOKUP(A37,'30.09.25'!A:F,6,FALSE) -> 16 | T37: =S37-Q37 -> 2 | U37: =VLOOKUP(A37,'31.10.25'!A:F,6,FALSE) -> 25 | V37: =U37-S37 -> 9 | W37: =VLOOKUP(A37,'30.11.25'!A:F,6,FALSE) -> 31 | X37: =W37-U37 -> 6 | Y37: =VLOOKUP(A37,'31.12.25'!A:B,2,FALSE) -> 35 | Z37: =Y37-W37 -> 4 | AA37: =Y37-B37 -> 35
A38: Подъемник коленчатый дизельный Zoomlion ZA14J | B38: =VLOOKUP(A38,'31.12.24'!A:F,6,FALSE) -> 127 | C38: =VLOOKUP(A38,'31.01.25'!A:F,6,FALSE) -> 127 | D38: =C38-B38 -> 0 | E38: =VLOOKUP(A38,'28.02.25'!A:F,6,FALSE) -> 131 | F38: =E38-C38 -> 4 | G38: =VLOOKUP(A38,'31.03.25'!A:F,6,FALSE) -> 147 | H38: =G38-E38 -> 16 | I38: =VLOOKUP(A38,'30.04.25'!A:F,6,FALSE) -> 159 | J38: =I38-G38 -> 12 | K38: =VLOOKUP(A38,'31.05.25'!A:F,6,FALSE) -> 160 | L38: =K38-I38 -> 1 | M38: =VLOOKUP(A38,'30.06.25'!A:F,6,FALSE) -> 179 | N38: =M38-K38 -> 19 | O38: =VLOOKUP(A38,'31.07.25'!A:F,6,FALSE) -> 183 | P38: =O38-M38 -> 4 | Q38: =VLOOKUP(A38,'31.08.25'!A:F,6,FALSE) -> 196 | R38: =Q38-O38 -> 13 | S38: =VLOOKUP(A38,'30.09.25'!A:F,6,FALSE) -> 207 | T38: =S38-Q38 -> 11 | U38: =VLOOKUP(A38,'31.10.25'!A:F,6,FALSE) -> 226 | V38: =U38-S38 -> 19 | W38: =VLOOKUP(A38,'30.11.25'!A:F,6,FALSE) -> 226 | X38: =W38-U38 -> 0 | Y38: =VLOOKUP(A38,'31.12.25'!A:B,2,FALSE) -> 226 | Z38: =Y38-W38 -> 0 | AA38: =Y38-B38 -> 99
A39: Подъемник коленчатый дизельный Zoomlion ZA16J | D39: =C39-B39 -> 0 | F39: =E39-C39 -> 0 | H39: =G39-E39 -> 0 | J39: =I39-G39 -> 0 | L39: =K39-I39 -> 0 | N39: =M39-K39 -> 0 | P39: =O39-M39 -> 0 | R39: =Q39-O39 -> 0 | T39: =S39-Q39 -> 0 | U39: =VLOOKUP(A39,'31.10.25'!A:F,6,FALSE) -> 10 | V39: =U39-S39 -> 10 | W39: =VLOOKUP(A39,'30.11.25'!A:F,6,FALSE) -> 15 | X39: =W39-U39 -> 5 | Y39: =VLOOKUP(A39,'31.12.25'!A:B,2,FALSE) -> 20 | Z39: =Y39-W39 -> 5 | AA39: =Y39-B39 -> 20
A40: Подъемник коленчатый дизельный Zoomlion ZA20J | B40: =VLOOKUP(A40,'31.12.24'!A:F,6,FALSE) -> 133 | C40: =VLOOKUP(A40,'31.01.25'!A:F,6,FALSE) -> 133 | D40: =C40-B40 -> 0 | E40: =VLOOKUP(A40,'28.02.25'!A:F,6,FALSE) -> 159 | F40: =E40-C40 -> 26 | G40: =VLOOKUP(A40,'31.03.25'!A:F,6,FALSE) -> 177 | H40: =G40-E40 -> 18 | I40: =VLOOKUP(A40,'30.04.25'!A:F,6,FALSE) -> 197 | J40: =I40-G40 -> 20 | K40: =VLOOKUP(A40,'31.05.25'!A:F,6,FALSE) -> 205 | L40: =K40-I40 -> 8 | M40: =VLOOKUP(A40,'30.06.25'!A:F,6,FALSE) -> 211 | N40: =M40-K40 -> 6 | O40: =VLOOKUP(A40,'31.07.25'!A:F,6,FALSE) -> 225 | P40: =O40-M40 -> 14 | Q40: =VLOOKUP(A40,'31.08.25'!A:F,6,FALSE) -> 230 | R40: =Q40-O40 -> 5 | S40: =VLOOKUP(A40,'30.09.25'!A:F,6,FALSE) -> 245 | T40: =S40-Q40 -> 15 | U40: =VLOOKUP(A40,'31.10.25'!A:F,6,FALSE) -> 245 | V40: =U40-S40 -> 0 | W40: =VLOOKUP(A40,'30.11.25'!A:F,6,FALSE) -> 246 | X40: =W40-U40 -> 1 | Y40: =VLOOKUP(A40,'31.12.25'!A:B,2,FALSE) -> 251 | Z40: =Y40-W40 -> 5 | AA40: =Y40-B40 -> 118
A41: Подъемник коленчатый дизельный Zoomlion ZA24J | B41: =VLOOKUP(A41,'31.12.24'!A:F,6,FALSE) -> 124 | C41: =VLOOKUP(A41,'31.01.25'!A:F,6,FALSE) -> 124 | D41: =C41-B41 -> 0 | E41: =VLOOKUP(A41,'28.02.25'!A:F,6,FALSE) -> 128 | F41: =E41-C41 -> 4 | G41: =VLOOKUP(A41,'31.03.25'!A:F,6,FALSE) -> 132 | H41: =G41-E41 -> 4 | I41: =VLOOKUP(A41,'30.04.25'!A:F,6,FALSE) -> 133 | J41: =I41-G41 -> 1 | K41: =VLOOKUP(A41,'31.05.25'!A:F,6,FALSE) -> 136 | L41: =K41-I41 -> 3 | M41: =VLOOKUP(A41,'30.06.25'!A:F,6,FALSE) -> 139 | N41: =M41-K41 -> 3 | O41: =VLOOKUP(A41,'31.07.25'!A:F,6,FALSE) -> 143 | P41: =O41-M41 -> 4 | Q41: =VLOOKUP(A41,'31.08.25'!A:F,6,FALSE) -> 148 | R41: =Q41-O41 -> 5 | S41: =VLOOKUP(A41,'30.09.25'!A:F,6,FALSE) -> 161 | T41: =S41-Q41 -> 13 | U41: =VLOOKUP(A41,'31.10.25'!A:F,6,FALSE) -> 178 | V41: =U41-S41 -> 17 | W41: =VLOOKUP(A41,'30.11.25'!A:F,6,FALSE) -> 178 | X41: =W41-U41 -> 0 | Y41: =VLOOKUP(A41,'31.12.25'!A:B,2,FALSE) -> 178 | Z41: =Y41-W41 -> 0 | AA41: =Y41-B41 -> 54
A42: Подъемник коленчатый дизельный Zoomlion ZA32J | B42: =VLOOKUP(A42,'31.12.24'!A:F,6,FALSE) -> 63 | C42: =VLOOKUP(A42,'31.01.25'!A:F,6,FALSE) -> 64 | D42: =C42-B42 -> 1 | E42: =VLOOKUP(A42,'28.02.25'!A:F,6,FALSE) -> 72 | F42: =E42-C42 -> 8 | G42: =VLOOKUP(A42,'31.03.25'!A:F,6,FALSE) -> 85 | H42: =G42-E42 -> 13 | I42: =VLOOKUP(A42,'30.04.25'!A:F,6,FALSE) -> 104 | J42: =I42-G42 -> 19 | K42: =VLOOKUP(A42,'31.05.25'!A:F,6,FALSE) -> 121 | L42: =K42-I42 -> 17 | M42: =VLOOKUP(A42,'30.06.25'!A:F,6,FALSE) -> 140 | N42: =M42-K42 -> 19 | O42: =VLOOKUP(A42,'31.07.25'!A:F,6,FALSE) -> 144 | P42: =O42-M42 -> 4 | Q42: =VLOOKUP(A42,'31.08.25'!A:F,6,FALSE) -> 150 | R42: =Q42-O42 -> 6 | S42: =VLOOKUP(A42,'30.09.25'!A:F,6,FALSE) -> 167 | T42: =S42-Q42 -> 17 | U42: =VLOOKUP(A42,'31.10.25'!A:F,6,FALSE) -> 176 | V42: =U42-S42 -> 9 | W42: =VLOOKUP(A42,'30.11.25'!A:F,6,FALSE) -> 182 | X42: =W42-U42 -> 6 | Y42: =VLOOKUP(A42,'31.12.25'!A:B,2,FALSE) -> 186 | Z42: =Y42-W42 -> 4 | AA42: =Y42-B42 -> 123
A43: Подъемник коленчатый дизельный Zoomlion ZA42J | D43: =C43-B43 -> 0 | F43: =E43-C43 -> 0 | H43: =G43-E43 -> 0 | J43: =I43-G43 -> 0 | L43: =K43-I43 -> 0 | N43: =M43-K43 -> 0 | P43: =O43-M43 -> 0 | R43: =Q43-O43 -> 0 | S43: =VLOOKUP(A43,'30.09.25'!A:F,6,FALSE) -> 7 | T43: =S43-Q43 -> 7 | U43: =VLOOKUP(A43,'31.10.25'!A:F,6,FALSE) -> 7 | V43: =U43-S43 -> 0 | W43: =VLOOKUP(A43,'30.11.25'!A:F,6,FALSE) -> 8 | X43: =W43-U43 -> 1 | Y43: =VLOOKUP(A43,'31.12.25'!A:B,2,FALSE) -> 8 | Z43: =Y43-W43 -> 0 | AA43: =Y43-B43 -> 8
...

Sheet 31.12.24
A1: Номенклатура | B1: Итого
B2: В аренде, шт | C2: На складе, шт | D2: Рем зона | E2: Брак | F2: Всего, шт | G2: Утилизация без брака, % | H2: Утилизация, %
A3: Подъемник коленчатый электрический Genie Z-33/18 | B3: 7 | C3: 9 | F3: 16 | G3: 43.75 | H3: 43.75
A4: Подъемник коленчатый дизельный Genie Z-45/25 | B4: 1 | F4: 1 | G4: 100 | H4: 100
A5: Подъемник коленчатый электрический Genie Z-45/25J DC | B5: 8 | C5: 4 | E5: 1 | F5: 13 | G5: 66.67 | H5: 61.54
A6: Подъемник коленчатый дизельный Genie Z-51/30J | B6: 4 | C6: 2 | F6: 6 | G6: 66.67 | H6: 66.67
A7: Подъемник коленчатый дизельный Genie Z-62/40 | B7: 2 | F7: 2 | G7: 100 | H7: 100
A8: Подъемник коленчатый электрический HAULOTTE HA12 IP | B8: 0 | C8: 1 | F8: 1 | H8: 0
A9: Подъемник коленчатый электрический HAULOTTE HA15 IP | B9: 4 | C9: 2 | E9: 1 | F9: 7 | G9: 66.67 | H9: 57.14
A10: Подъемник коленчатый дизельный HAULOTTE HA16RTJ | B10: 1 | C10: 1 | F10: 2 | G10: 50 | H10: 50
A11: Подъемник коленчатый дизельный HAULOTTE HA20RTJ | B11: 6 | C11: 1 | F11: 7 | G11: 85.71 | H11: 85.71
A12: Подъемник коленчатый дизельный HAULOTTE HA26RTJ PRO | B12: 3 | C12: 2 | E12: 1 | F12: 6 | G12: 60 | H12: 50
A13: Подъемник коленчатый дизельный JLG 520AJ | B13: 6 | C13: 3 | F13: 9 | G13: 66.67 | H13: 66.67
A14: Подъемник коленчатый дизельный JLG 600AJ | B14: 2 | C14: 1 | F14: 3 | G14: 66.67 | H14: 66.67
A15: Подъемник коленчатый электрический JLG E450AJ | B15: 0 | C15: 1 | E15: 1 | F15: 2 | H15: 0
A16: Подъемник коленчатый дизельный MANITOU 200 ATJ-X | B16: 3 | F16: 3 | G16: 100 | H16: 100
A17: Подъемник коленчатый дизельный MANITOU 180 ATJ | B17: 0 | C17: 1 | F17: 1 | H17: 0
A18: Подъемник мачтовый электрический Aurora AMWP3.6-6100 (Rees) | B18: 3 | C18: 2 | F18: 5 | G18: 60 | H18: 60
A19: Подъемник мачтовый электрический Aurora AMWP4.8-6100 (Rees) | B19: 4 | E19: 2 | F19: 6 | G19: 100 | H19: 66.67
A20: Подъемник мачтовый электрический Aurora AMWP7.5-1100 (Rees) | B20: 0 | E20: 1 | F20: 1 | H20: 0
A21: Подъемник мачтовый электрический Aurora AMWP7.5-2100 (Rees) | B21: 0 | C21: 2 | F21: 2 | H21: 0
A22: Подъемник мачтовый электрический Aurora AMWP9-2100 (Rees) | B22: 0 | C22: 1 | F22: 1 | H22: 0
A23: Подъемник ножничный электрический Aurora AS0808 (RS) | B23: 70 | C23: 31 | E23: 1 | F23: 102 | G23: 69.31 | H23: 68.63
A24: Подъемник ножничный электрический Aurora AS1012 (RS) | B24: 15 | C24: 8 | F24: 23 | G24: 65.22 | H24: 65.22
A25: Подъемник ножничный электрический Aurora JCPT0307 (Rees) | B25: 0 | C25: 4 | E25: 1 | F25: 5 | H25: 0
A26: Подъемник ножничный электрический Aurora JCPT0407 (Rees) | B26: 0 | C26: 3 | E26: 1 | F26: 4 | H26: 0
A27: Подъемник ножничный электрический Genie GS 2032 | B27: 2 | F27: 2 | G27: 100 | H27: 100
A28: Подъемник ножничный электрический Genie GS 2632 | B28: 0 | C28: 1 | F28: 1 | H28: 0
A29: Подъемник ножничный электрический Genie GS 3246 | B29: 2 | C29: 1 | F29: 3 | G29: 66.67 | H29: 66.67
A30: Подъемник ножничный электрический Genie GS 4047 | B30: 0 | C30: 2 | F30: 2 | H30: 0
A31: Подъемник ножничный электрический Haulotte COMPACT 10N | B31: 1 | C31: 1 | F31: 2 | G31: 50 | H31: 50
A32: Подъемник ножничный электрический HAULOTTE COMPACT 14 | B32: 2 | F32: 2 | G32: 100 | H32: 100
A33: Подъемник ножничный электрический JLG 2630ES | B33: 4 | C33: 5 | F33: 9 | G33: 44.44 | H33: 44.44
A34: Подъемник ножничный электрический JLG R2632 | B34: 0 | C34: 1 | F34: 1 | H34: 0
A35: Подъемник ножничный электрический JLG R4045 | B35: 1 | F35: 1 | G35: 100 | H35: 100
A36: Подъемник ножничный электрический Zoomlion ZS1414DC | B36: 3 | C36: 2 | F36: 5 | G36: 60 | H36: 60
A37: Подъемник коленчатый дизельный Dingli BA16CRT2 | B37: 13 | C37: 4 | F37: 17 | G37: 76.47 | H37: 76.47
A38: Подъемник коленчатый дизельный Dingli BA16СRT | B38: 10 | C38: 2 | E38: 1 | F38: 13 | G38: 83.33 | H38: 76.92
A39: Подъемник коленчатый дизельный Dingli BA18CRT | B39: 9 | C39: 4 | F39: 13 | G39: 69.23 | H39: 69.23
A40: Подъемник коленчатый дизельный Dingli BA18CRT2 | B40: 38 | C40: 30 | F40: 68 | G40: 55.88 | H40: 55.88
...

Sheet 31.01.25
A1: Номенклатура | B1: Итого
B2: В аренде, шт | C2: На складе, шт | D2: Рем зона | E2: Брак | F2: Всего, шт | G2: Утилизация без брака, % | H2: Утилизация, %
A3: Подъемник коленчатый электрический Genie Z-33/18 | B3: 8 | C3: 8 | F3: 16 | G3: 50 | H3: 50
A4: Подъемник коленчатый дизельный Genie Z-45/25 | B4: 1 | F4: 1 | G4: 100 | H4: 100
A5: Подъемник коленчатый электрический Genie Z-45/25J DC | B5: 9 | C5: 3 | E5: 1 | F5: 13 | G5: 75 | H5: 69.23
A6: Подъемник коленчатый дизельный Genie Z-51/30J | B6: 2 | C6: 4 | F6: 6 | G6: 33.33 | H6: 33.33
A7: Подъемник коленчатый дизельный Genie Z-62/40 | B7: 1 | C7: 1 | F7: 2 | G7: 50 | H7: 50
A8: Подъемник коленчатый электрический HAULOTTE HA12 IP | B8: 0 | C8: 1 | F8: 1 | H8: 0
A9: Подъемник коленчатый электрический HAULOTTE HA15 IP | B9: 3 | C9: 3 | E9: 1 | F9: 7 | G9: 50 | H9: 42.86
A10: Подъемник коленчатый дизельный HAULOTTE HA16RTJ | B10: 2 | F10: 2 | G10: 100 | H10: 100
A11: Подъемник коленчатый дизельный HAULOTTE HA20RTJ | B11: 5 | C11: 2 | F11: 7 | G11: 71.43 | H11: 71.43
A12: Подъемник коленчатый дизельный HAULOTTE HA26RTJ PRO | B12: 3 | C12: 3 | F12: 6 | G12: 50 | H12: 50
A13: Подъемник коленчатый дизельный JLG 520AJ | B13: 7 | C13: 2 | F13: 9 | G13: 77.78 | H13: 77.78
A14: Подъемник коленчатый дизельный JLG 600AJ | B14: 1 | C14: 2 | F14: 3 | G14: 33.33 | H14: 33.33
A15: Подъемник коленчатый электрический JLG E450AJ | B15: 0 | C15: 1 | E15: 1 | F15: 2 | H15: 0
A16: Подъемник коленчатый дизельный MANITOU 200 ATJ-X | B16: 3 | F16: 3 | G16: 100 | H16: 100
A17: Подъемник коленчатый дизельный MANITOU 180 ATJ | B17: 1 | F17: 1 | G17: 100 | H17: 100
A18: Подъемник мачтовый электрический Aurora AMWP3.6-6100 (Rees) | B18: 3 | C18: 2 | F18: 5 | G18: 60 | H18: 60
A19: Подъемник мачтовый электрический Aurora AMWP4.8-6100 (Rees) | B19: 3 | C19: 1 | E19: 2 | F19: 6 | G19: 75 | H19: 50
A20: Подъемник мачтовый электрический Aurora AMWP7.5-1100 (Rees) | B20: 0 | E20: 1 | F20: 1 | H20: 0
A21: Подъемник мачтовый электрический Aurora AMWP7.5-2100 (Rees) | B21: 0 | C21: 2 | F21: 2 | H21: 0
A22: Подъемник мачтовый электрический Aurora AMWP9-2100 (Rees) | B22: 1 | F22: 1 | G22: 100 | H22: 100
A23: Подъемник ножничный электрический Aurora AS0808 (RS) | B23: 70 | C23: 31 | E23: 1 | F23: 102 | G23: 69.31 | H23: 68.63
A24: Подъемник ножничный электрический Aurora AS1012 (RS) | B24: 17 | C24: 6 | F24: 23 | G24: 73.91 | H24: 73.91
A25: Подъемник ножничный электрический Aurora JCPT0307 (Rees) | B25: 1 | C25: 3 | E25: 1 | F25: 5 | G25: 25 | H25: 20
A26: Подъемник ножничный электрический Aurora JCPT0407 (Rees) | B26: 0 | C26: 3 | E26: 1 | F26: 4 | H26: 0
A27: Подъемник ножничный электрический Genie GS 2032 | B27: 2 | F27: 2 | G27: 100 | H27: 100
A28: Подъемник ножничный электрический Genie GS 2632 | B28: 0 | C28: 1 | F28: 1 | H28: 0
A29: Подъемник ножничный электрический Genie GS 3246 | B29: 2 | C29: 1 | F29: 3 | G29: 66.67 | H29: 66.67
A30: Подъемник ножничный электрический Genie GS 4047 | B30: 0 | C30: 2 | F30: 2 | H30: 0
A31: Подъемник ножничный электрический Haulotte COMPACT 10N | B31: 1 | C31: 1 | F31: 2 | G31: 50 | H31: 50
A32: Подъемник ножничный электрический HAULOTTE COMPACT 14 | B32: 1 | C32: 1 | F32: 2 | G32: 50 | H32: 50
A33: Подъемник ножничный электрический JLG 2630ES | B33: 5 | C33: 4 | F33: 9 | G33: 55.56 | H33: 55.56
A34: Подъемник ножничный электрический JLG R2632 | B34: 0 | C34: 1 | F34: 1 | H34: 0
A35: Подъемник ножничный электрический JLG R4045 | B35: 0 | C35: 1 | F35: 1 | H35: 0
A36: Подъемник ножничный электрический Zoomlion ZS1414DC | B36: 2 | C36: 3 | F36: 5 | G36: 40 | H36: 40
A37: Подъемник коленчатый дизельный Dingli BA16CRT2 | B37: 13 | C37: 4 | F37: 17 | G37: 76.47 | H37: 76.47
A38: Подъемник коленчатый дизельный Dingli BA16СRT | B38: 10 | C38: 2 | E38: 1 | F38: 13 | G38: 83.33 | H38: 76.92
A39: Подъемник коленчатый дизельный Dingli BA18CRT | B39: 8 | C39: 5 | F39: 13 | G39: 61.54 | H39: 61.54
A40: Подъемник коленчатый дизельный Dingli BA18CRT2 | B40: 54 | C40: 16 | F40: 70 | G40: 77.14 | H40: 77.14
...

Sheet 28.02.25
A1: Номенклатура | B1: Итого
B2: В аренде, шт | C2: На складе, шт | D2: Рем зона | E2: Брак | F2: Всего, шт | G2: Утилизация без брака, % | H2: Утилизация, %
A3: Подъемник коленчатый электрический Genie Z-33/18 | B3: 10 | C3: 6 | F3: 16 | G3: 62.5 | H3: 62.5
A4: Подъемник коленчатый дизельный Genie Z-45/25 | B4: 1 | F4: 1 | G4: 100 | H4: 100
A5: Подъемник коленчатый электрический Genie Z-45/25J DC | B5: 10 | C5: 2 | E5: 1 | F5: 13 | G5: 83.33 | H5: 76.92
A6: Подъемник коленчатый дизельный Genie Z-51/30J | B6: 3 | C6: 3 | F6: 6 | G6: 50 | H6: 50
A7: Подъемник коленчатый дизельный Genie Z-62/40 | B7: 1 | C7: 1 | F7: 2 | G7: 50 | H7: 50
A8: Подъемник коленчатый электрический HAULOTTE HA12 IP | B8: 0 | C8: 1 | F8: 1 | H8: 0
A9: Подъемник коленчатый электрический HAULOTTE HA15 IP | B9: 4 | C9: 2 | E9: 1 | F9: 7 | G9: 66.67 | H9: 57.14
A10: Подъемник коленчатый дизельный HAULOTTE HA16RTJ | B10: 2 | F10: 2 | G10: 100 | H10: 100
A11: Подъемник коленчатый дизельный HAULOTTE HA20RTJ | B11: 5 | C11: 2 | F11: 7 | G11: 71.43 | H11: 71.43
A12: Подъемник коленчатый дизельный HAULOTTE HA26RTJ PRO | B12: 4 | C12: 2 | F12: 6 | G12: 66.67 | H12: 66.67
A13: Подъемник коленчатый дизельный JLG 520AJ | B13: 7 | C13: 2 | F13: 9 | G13: 77.78 | H13: 77.78
A14: Подъемник коленчатый дизельный JLG 600AJ | B14: 1 | C14: 2 | F14: 3 | G14: 33.33 | H14: 33.33
A15: Подъемник коленчатый электрический JLG E450AJ | B15: 0 | C15: 1 | E15: 1 | F15: 2 | H15: 0
A16: Подъемник коленчатый дизельный MANITOU 200 ATJ-X | B16: 3 | F16: 3 | G16: 100 | H16: 100
A17: Подъемник коленчатый дизельный MANITOU 180 ATJ | B17: 0 | C17: 1 | F17: 1 | H17: 0
A18: Подъемник мачтовый электрический Aurora AMWP3.6-6100 (Rees) | B18: 4 | C18: 1 | F18: 5 | G18: 80 | H18: 80
A19: Подъемник мачтовый электрический Aurora AMWP4.8-6100 (Rees) | B19: 4 | C19: 1 | E19: 1 | F19: 6 | G19: 80 | H19: 66.67
A20: Подъемник мачтовый электрический Aurora AMWP7.5-1100 (Rees) | B20: 0 | E20: 1 | F20: 1 | H20: 0
A21: Подъемник мачтовый электрический Aurora AMWP7.5-2100 (Rees) | B21: 0 | C21: 2 | F21: 2 | H21: 0
A22: Подъемник мачтовый электрический Aurora AMWP9-2100 (Rees) | B22: 1 | F22: 1 | G22: 100 | H22: 100
A23: Подъемник ножничный электрический Aurora AS0808 (RS) | B23: 72 | C23: 29 | E23: 1 | F23: 102 | G23: 71.29 | H23: 70.59
A24: Подъемник ножничный электрический Aurora AS1012 (RS) | B24: 15 | C24: 8 | F24: 23 | G24: 65.22 | H24: 65.22
A25: Подъемник ножничный электрический Aurora JCPT0307 (Rees) | B25: 1 | C25: 3 | E25: 1 | F25: 5 | G25: 25 | H25: 20
A26: Подъемник ножничный электрический Aurora JCPT0407 (Rees) | B26: 0 | C26: 3 | E26: 1 | F26: 4 | H26: 0
A27: Подъемник ножничный электрический Genie GS 2032 | B27: 1 | C27: 1 | F27: 2 | G27: 50 | H27: 50
A28: Подъемник ножничный электрический Genie GS 2632 | B28: 0 | C28: 1 | F28: 1 | H28: 0
A29: Подъемник ножничный электрический Genie GS 3246 | B29: 1 | C29: 2 | F29: 3 | G29: 33.33 | H29: 33.33
A30: Подъемник ножничный электрический Genie GS 4047 | B30: 0 | C30: 2 | F30: 2 | H30: 0
A31: Подъемник ножничный электрический Haulotte COMPACT 10N | B31: 0 | C31: 2 | F31: 2 | H31: 0
A32: Подъемник ножничный электрический HAULOTTE COMPACT 14 | B32: 1 | C32: 1 | F32: 2 | G32: 50 | H32: 50
A33: Подъемник ножничный электрический JLG 2630ES | B33: 3 | C33: 6 | F33: 9 | G33: 33.33 | H33: 33.33
A34: Подъемник ножничный электрический JLG R2632 | B34: 0 | C34: 1 | F34: 1 | H34: 0
A35: Подъемник ножничный электрический JLG R4045 | B35: 0 | C35: 1 | F35: 1 | H35: 0
A36: Подъемник ножничный электрический Zoomlion ZS1414DC | B36: 3 | C36: 2 | F36: 5 | G36: 60 | H36: 60
A37: Подъемник коленчатый дизельный Dingli BA16CRT2 | B37: 12 | C37: 5 | F37: 17 | G37: 70.59 | H37: 70.59
A38: Подъемник коленчатый дизельный Dingli BA16СRT | B38: 7 | C38: 5 | E38: 1 | F38: 13 | G38: 58.33 | H38: 53.85
A39: Подъемник коленчатый дизельный Dingli BA18CRT | B39: 12 | D39: 1 | F39: 13 | G39: 92.31 | H39: 92.31
A40: Подъемник коленчатый дизельный Dingli BA18CRT2 | B40: 62 | C40: 22 | F40: 84 | G40: 73.81 | H40: 73.81
...

Sheet 31.03.25
A1: Номенклатура | B1: Итого
B2: В аренде, шт | C2: На складе, шт | D2: Рем зона | E2: Брак | F2: Всего, шт | G2: Утилизация без брака, % | H2: Утилизация, %
A3: Подъемник коленчатый электрический Genie Z-33/18 | B3: 11 | C3: 5 | F3: 16 | G3: 68.75 | H3: 68.75
A4: Подъемник коленчатый дизельный Genie Z-45/25 | B4: 1 | F4: 1 | G4: 100 | H4: 100
A5: Подъемник коленчатый электрический Genie Z-45/25J DC | B5: 5 | C5: 7 | E5: 1 | F5: 13 | G5: 41.67 | H5: 38.46
A6: Подъемник коленчатый дизельный Genie Z-51/30J | B6: 3 | C6: 3 | F6: 6 | G6: 50 | H6: 50
A7: Подъемник коленчатый дизельный Genie Z-62/40 | B7: 1 | C7: 1 | F7: 2 | G7: 50 | H7: 50
A8: Подъемник коленчатый электрический HAULOTTE HA12 IP | B8: 1 | F8: 1 | G8: 100 | H8: 100
A9: Подъемник коленчатый электрический HAULOTTE HA15 IP | B9: 4 | C9: 2 | E9: 1 | F9: 7 | G9: 66.67 | H9: 57.14
A10: Подъемник коленчатый дизельный HAULOTTE HA16RTJ | B10: 1 | C10: 1 | F10: 2 | G10: 50 | H10: 50
A11: Подъемник коленчатый дизельный HAULOTTE HA20RTJ | B11: 6 | C11: 1 | F11: 7 | G11: 85.71 | H11: 85.71
A12: Подъемник коленчатый дизельный HAULOTTE HA26RTJ PRO | B12: 4 | C12: 2 | F12: 6 | G12: 66.67 | H12: 66.67
A13: Подъемник коленчатый дизельный JLG 520AJ | B13: 7 | C13: 2 | F13: 9 | G13: 77.78 | H13: 77.78
A14: Подъемник коленчатый дизельный JLG 600AJ | B14: 2 | C14: 1 | F14: 3 | G14: 66.67 | H14: 66.67
A15: Подъемник коленчатый электрический JLG E450AJ | B15: 0 | C15: 1 | E15: 1 | F15: 2 | H15: 0
A16: Подъемник коленчатый дизельный MANITOU 200 ATJ-X | B16: 3 | F16: 3 | G16: 100 | H16: 100
A17: Подъемник коленчатый дизельный MANITOU 180 ATJ | B17: 1 | F17: 1 | G17: 100 | H17: 100
A18: Подъемник мачтовый электрический Aurora AMWP3.6-6100 (Rees) | B18: 2 | C18: 3 | F18: 5 | G18: 40 | H18: 40
A19: Подъемник мачтовый электрический Aurora AMWP4.8-6100 (Rees) | B19: 4 | C19: 1 | E19: 1 | F19: 6 | G19: 80 | H19: 66.67
A20: Подъемник мачтовый электрический Aurora AMWP7.5-1100 (Rees) | B20: 0 | E20: 1 | F20: 1 | H20: 0
A21: Подъемник мачтовый электрический Aurora AMWP7.5-2100 (Rees) | B21: 0 | C21: 2 | F21: 2 | H21: 0
A22: Подъемник мачтовый электрический Aurora AMWP9-2100 (Rees) | B22: 1 | F22: 1 | G22: 100 | H22: 100
A23: Подъемник ножничный электрический Aurora AS0808 (RS) | B23: 73 | C23: 28 | E23: 1 | F23: 102 | G23: 72.28 | H23: 71.57
A24: Подъемник ножничный электрический Aurora AS1012 (RS) | B24: 14 | C24: 9 | F24: 23 | G24: 60.87 | H24: 60.87
A25: Ножничный подъемник Aurora AS1416 (RS) | B25: 1 | F25: 1 | G25: 100 | H25: 100
A26: Подъемник ножничный электрический Aurora JCPT0307 (Rees) | B26: 0 | C26: 4 | E26: 1 | F26: 5 | H26: 0
A27: Подъемник ножничный электрический Aurora JCPT0407 (Rees) | B27: 1 | C27: 2 | E27: 1 | F27: 4 | G27: 33.33 | H27: 25
A28: Подъемник ножничный электрический Genie GS 2032 | B28: 1 | C28: 1 | F28: 2 | G28: 50 | H28: 50
A29: Подъемник ножничный электрический Genie GS 2632 | B29: 0 | C29: 1 | F29: 1 | H29: 0
A30: Подъемник ножничный электрический Genie GS 3246 | B30: 1 | C30: 2 | F30: 3 | G30: 33.33 | H30: 33.33
A31: Подъемник ножничный электрический Genie GS 4047 | B31: 0 | C31: 2 | F31: 2 | H31: 0
A32: Подъемник ножничный электрический Haulotte COMPACT 10N | B32: 0 | C32: 1 | E32: 1 | F32: 2 | H32: 0
